<?xml version="1.0" ?>
<!-- =================================================================================== -->
<!-- |    This document was autogenerated by xacro from /home/clynamen/teamdiana/gazebo/models/definitions/rover_amalia/model.xacro | -->
<!-- |    EDITING THIS FILE BY HAND IS NOT RECOMMENDED                                 | -->
<!-- =================================================================================== -->
<sdf version="1.5">
  <model name="rover_amalia">
    <pose>0 0 0 0 0 0</pose>
    <static>0</static>
    <!--main components-->
    <link name="rover_amalia_turret_bar">
      <pose>0.195 0 0.45 0 0 0</pose>
      <inertial>
        <pose>0 0 0 0 0 0</pose>
        <mass>1</mass>
        <inertia>
          <ixx>100</ixx>
          <ixy>0</ixy>
          <ixz>0</ixz>
          <iyy>100</iyy>
          <iyz>0</iyz>
          <izz>100</izz>
        </inertia>
      </inertial>
      <collision name="rover_amalia_turret_bar_collision">
        <pose>0 0 0.1 0 0 0</pose>
        <geometry>
          <cylinder>
            <length>0.2</length>
            <radius>0.01</radius>
          </cylinder>
        </geometry>
      </collision>
      <visual name="rover_amalia_turret_bar_visual">
        <pose>0 0 0.1 0 0 0</pose>
        <geometry>
          <cylinder>
            <length>0.2</length>
            <radius>0.01</radius>
          </cylinder>
        </geometry>
      </visual>
      <self_collide>0</self_collide>
      <kinematic>0</kinematic>
      <gravity>1</gravity>
    </link>
    <link name="rover_amalia_turret_pan_base">
      <pose>0.195 0 0.66 0 0 0</pose>
      <inertial>
        <pose>0 0 0 0 0 0</pose>
        <mass>1</mass>
        <inertia>
          <ixx>100</ixx>
          <ixy>0</ixy>
          <ixz>0</ixz>
          <iyy>100</iyy>
          <iyz>0</iyz>
          <izz>100</izz>
        </inertia>
      </inertial>
      <visual name="rover_amalia_turret_pan_base_visual">
        <pose>-0.016 -0.02 0.015 0 0 0</pose>
        <geometry>
          <mesh>
            <uri>model://rover_amalia_turret/meshes/pantilt_pan.dae</uri>
          </mesh>
        </geometry>
      </visual>
      <velocity_decay>
        <linear>0</linear>
        <angular>0</angular>
      </velocity_decay>
      <self_collide>0</self_collide>
      <kinematic>0</kinematic>
      <gravity>1</gravity>
    </link>
    <link name="rover_amalia_turret_tilt_base">
      <pose>0.195 -0.01 0.69 0 0 0</pose>
      <inertial>
        <pose>0 0 0 0 0 0</pose>
        <mass>2</mass>
        <inertia>
          <ixx>200.001</ixx>
          <ixy>0</ixy>
          <ixz>0</ixz>
          <iyy>200.001</iyy>
          <iyz>0</iyz>
          <izz>200</izz>
        </inertia>
      </inertial>
      <collision name="rover_amalia_turret_tilt_base_collision">
        <pose>0 0 0 0 0 0</pose>
        <pose>0.195 -0.01 0.69 0 0 0</pose>
        <geometry>
          <box>
            <size>0.06 0.02 0.04</size>
          </box>
        </geometry>
        <max_contacts>10</max_contacts>
        <surface>
          <contact>
            <ode/>
          </contact>
          <bounce/>
          <friction>
            <ode/>
          </friction>
        </surface>
      </collision>
      <visual name="rover_amalia_turret_tilt_base_visual">
        <pose>0 0 0 0 0 0</pose>
        <geometry>
          <mesh>
            <uri>model://rover_amalia_turret/meshes/pantilt_tilt.dae</uri>
          </mesh>
        </geometry>
      </visual>
      <visual name="rover_amalia_turret_camera_set_visual">
        <pose>0 0 0.052 0 0 0</pose>
        <geometry>
          <mesh>
            <uri>model://rover_amalia_turret/meshes/pantilt_payload.dae</uri>
          </mesh>
        </geometry>
      </visual>
      <sensor name="depth_camera" type="depth">
        <pose>0 0 0 0 3.1415926 0</pose>
        <camera>
          <horizontal_fov>1.578</horizontal_fov>
          <image>
            <width>640</width>
            <height>480</height>
            <format>R8G8B8</format>
          </image>
          <clip>
            <near>0.4</near>
            <far>100</far>
          </clip>
        </camera>
        <plugin filename="libgazebo_ros_depth_camera.so" name="depth_camera_plugin">
          <alwaysOn>1</alwaysOn>
          <updateRate>10.0</updateRate>
          <imageTopicName>image_raw</imageTopicName>
          <depthImageTopicName>depth_raw</depthImageTopicName>
          <depthImageCameraInfoTopicName>camera_info</depthImageCameraInfoTopicName>
          <pointCloudTopicName>points</pointCloudTopicName>
          <cameraInfoTopicName>camera_info</cameraInfoTopicName>
          <cameraName>depth_cam</cameraName>
          <frameName>/base_link</frameName>
          <pointCloudCutoff>0.001</pointCloudCutoff>
          <distortionK1>0.0</distortionK1>
          <distortionK2>0.0</distortionK2>
          <distortionK3>0.0</distortionK3>
          <distortionT1>0.0</distortionT1>
          <distortionT2>0.0</distortionT2>
        </plugin>
        <always_on>true</always_on>
        <update_rate>10.0</update_rate>
      </sensor>
      <sensor name="camera" type="multicamera">
        <always_on>1</always_on>
        <update_rate>30</update_rate>
        <visualize>true</visualize>
        <camera name="left">
          <pose>0 0 0 0 3.14 0</pose>
          <horizontal_fov>1.047</horizontal_fov>
          <image>
            <width>320</width>
            <height>240</height>
          </image>
          <clip>
            <near>0.4</near>
            <far>100</far>
          </clip>
        </camera>
        <camera name="right">
          <pose>0 -0.2 0 0 3.14 0</pose>
          <horizontal_fov>1.047</horizontal_fov>
          <image>
            <width>320</width>
            <height>240</height>
          </image>
          <clip>
            <near>0.4</near>
            <far>100</far>
          </clip>
        </camera>
        <plugin filename="libgazebo_ros_multicamera.so" name="stereo_camera_controller">
          <alwaysOn>true</alwaysOn>
          <updateRate>0.0</updateRate>
          <cameraName>camera</cameraName>
          <imageTopicName>image_raw</imageTopicName>
          <cameraInfoTopicName>camera_info</cameraInfoTopicName>
          <frameName>left_camera_optical_frame</frameName>
          <!--<rightFrameName>right_camera_optical_frame</rightFrameName>-->
          <hackBaseline>0.07</hackBaseline>
          <distortionK1>0.0</distortionK1>
          <distortionK2>0.0</distortionK2>
          <distortionK3>0.0</distortionK3>
          <distortionT1>0.0</distortionT1>
          <distortionT2>0.0</distortionT2>
        </plugin>
      </sensor>
      <velocity_decay>
        <linear>0</linear>
        <angular>0</angular>
      </velocity_decay>
      <self_collide>0</self_collide>
      <kinematic>0</kinematic>
      <gravity>1</gravity>
    </link>
    <joint name="rover_amalia_turret_pan" type="revolute">
      <child>rover_amalia_turret_pan_base</child>
      <parent>rover_amalia_turret_bar</parent>
      <axis>
        <xyz>0 0 1</xyz>
        <limit>
          <lower>-1e-16</lower>
          <upper>1e-16</upper>
        </limit>
        <dynamics/>
      </axis>
    </joint>
    <joint name="rover_amalia_turret_tilt" type="revolute">
      <child>rover_amalia_turret_tilt_base</child>
      <parent>rover_amalia_turret_pan_base</parent>
      <axis>
        <xyz>0 1 0</xyz>
        <limit>
          <lower>-1e-16</lower>
          <upper>1e-16</upper>
        </limit>
        <dynamics/>
      </axis>
    </joint>
    <link name="rover_amalia_chassis">
      <pose>0 0 0.35 0 0 0</pose>
      <inertial>
        <pose>0.0216667 0 -0.0215556 0 -0 0</pose>
        <!--temporary set the mass to 1000, change when all the inertial will be ok-->
        <mass>100</mass>
        <inertia>
          <ixx>900.12</ixx>
          <ixy>-3.46945e-18</ixy>
          <ixz>-0.0139533</ixz>
          <iyy>900.352</iyy>
          <iyz>0</iyz>
          <izz>900.455</izz>
        </inertia>
      </inertial>
      <visual name="rover_amalia_chassis_body_visual">
        <pose>0 0 0 0 0 0</pose>
        <geometry>
          <mesh>
            <uri>model://rover_amalia_chassis/meshes/chassis.dae</uri>
          </mesh>
        </geometry>
      </visual>
      <collision name="rover_amalia_chassis_body_collision">
        <pose>0 0 0 0 0 0</pose>
        <geometry>
          <box>
            <size>0.492 0.334 0.215</size>
          </box>
        </geometry>
        <max_contacts>10</max_contacts>
      </collision>
      <collision name="rover_amalia_chassis_turret_base_collision">
        <pose>0.195 0.05 0.073 0 0 0</pose>
        <geometry>
          <box>
            <size>0.089 0.064 0.046</size>
          </box>
        </geometry>
        <max_contacts>10</max_contacts>
      </collision>
      <visual name="rover_amalia_chassis_turret_base_visual">
        <pose>0.195 0.05 0.073 0 0 0</pose>
        <geometry>
          <box>
            <size>0.089 0.064 0.046</size>
          </box>
        </geometry>
      </visual>
      <visual name="rover_amalia_chassis_front_up_rangefinder_visual">
        <pose>0.246 0 -0.05 0 -0 0</pose>
        <geometry>
          <box>
            <size>0.01 0.03 0.01</size>
          </box>
        </geometry>
      </visual>
      <visual name="rover_amalia_chassis_front_down_rangefinder_visual">
        <pose>0.236 0 -0.06 0 1.57 0</pose>
        <geometry>
          <box>
            <size>0.01 0.03 0.01</size>
          </box>
        </geometry>
      </visual>
      <visual name="rover_amalia_chassis_rear_up_rangefinder_visual">
        <pose>-0.246 0 -0.05 3.14159 0.00159265 3.14159</pose>
        <geometry>
          <box>
            <size>0.01 0.03 0.01</size>
          </box>
        </geometry>
      </visual>
      <visual name="rover_amalia_chassis_rear_down_rangefinder_visual">
        <pose>-0.236 0 -0.06 0 1.57 0</pose>
        <geometry>
          <box>
            <size>0.01 0.03 0.01</size>
          </box>
        </geometry>
      </visual>
      <self_collide>0</self_collide>
      <kinematic>0</kinematic>
      <gravity>1</gravity>
    </link>
    <link name="rover_amalia_leg_bar_f_r">
      <pose>0.13284 0.175 0.19 0 0 0</pose>
      <collision name="leg_bar_f_r_bar_collision">
        <geometry>
          <cylinder>
            <length>0.22</length>
            <radius>0.008</radius>
          </cylinder>
        </geometry>
        <max_contacts>10</max_contacts>
        <surface>
          <contact>
            <ode/>
          </contact>
          <bounce/>
          <friction>
            <ode/>
          </friction>
        </surface>
      </collision>
      <visual name="rover_amalia_leg_bar_f_r_bar_visual">
        <pose>0 0 0 0 0 0</pose>
        <geometry>
          <cylinder>
            <length>0.22</length>
            <radius>0.008</radius>
          </cylinder>
        </geometry>
      </visual>
    </link>
    <link name="rover_amalia_leg_wheel_f_r">
      <pose>0.13284 0.219 0.08 0 0 0</pose>
      <inertial>
        <pose>0 0 0 0 0 0</pose>
        <mass>1</mass>
        <inertia>
          <ixx>100</ixx>
          <ixy>0</ixy>
          <ixz>0</ixz>
          <iyy>100</iyy>
          <iyz>0</iyz>
          <izz>100</izz>
        </inertia>
      </inertial>
      <collision name="rover_amalia_leg_wheel_f_r_collision">
        <pose>0 0 0 1.5707963 0 0</pose>
        <geometry>
          <cylinder>
            <length>0.07</length>
            <radius>0.08</radius>
          </cylinder>
        </geometry>
        <max_contacts>10</max_contacts>
      </collision>
      <visual name="rover_amalia_leg_wheel_f_r_visual">
        <pose>0 0 0 0 0 0</pose>
        <geometry>
          <mesh>
            <uri>model://rover_amalia_leg/meshes/wheel.dae</uri>
          </mesh>
        </geometry>
      </visual>
      <self_collide>0</self_collide>
      <kinematic>0</kinematic>
      <gravity>1</gravity>
    </link>
    <joint name="rover_amalia_leg_shaft_f_r" type="revolute">
      <child>rover_amalia_leg_wheel_f_r</child>
      <parent>rover_amalia_leg_bar_f_r</parent>
      <axis>
        <xyz>0 1 0</xyz>
        <limit>
          <lower>-1e+16</lower>
          <upper>1e+16</upper>
        </limit>
        <use_parent_model_frame>1</use_parent_model_frame>
      </axis>
    </joint>
    <link name="rover_amalia_leg_bar_f_l">
      <pose>0.13284 -0.175 0.19 0 0 0</pose>
      <collision name="leg_bar_f_l_bar_collision">
        <geometry>
          <cylinder>
            <length>0.22</length>
            <radius>0.008</radius>
          </cylinder>
        </geometry>
        <max_contacts>10</max_contacts>
        <surface>
          <contact>
            <ode/>
          </contact>
          <bounce/>
          <friction>
            <ode/>
          </friction>
        </surface>
      </collision>
      <visual name="rover_amalia_leg_bar_f_l_bar_visual">
        <pose>0 0 0 0 0 0</pose>
        <geometry>
          <cylinder>
            <length>0.22</length>
            <radius>0.008</radius>
          </cylinder>
        </geometry>
      </visual>
    </link>
    <link name="rover_amalia_leg_wheel_f_l">
      <pose>0.13284 -0.219 0.08 0 0 0</pose>
      <inertial>
        <pose>0 0 0 0 0 0</pose>
        <mass>1</mass>
        <inertia>
          <ixx>100</ixx>
          <ixy>0</ixy>
          <ixz>0</ixz>
          <iyy>100</iyy>
          <iyz>0</iyz>
          <izz>100</izz>
        </inertia>
      </inertial>
      <collision name="rover_amalia_leg_wheel_f_l_collision">
        <pose>0 0 0 1.5707963 0 0</pose>
        <geometry>
          <cylinder>
            <length>0.07</length>
            <radius>0.08</radius>
          </cylinder>
        </geometry>
        <max_contacts>10</max_contacts>
      </collision>
      <visual name="rover_amalia_leg_wheel_f_l_visual">
        <pose>0 0 0 0 0 0</pose>
        <geometry>
          <mesh>
            <uri>model://rover_amalia_leg/meshes/wheel.dae</uri>
          </mesh>
        </geometry>
      </visual>
      <self_collide>0</self_collide>
      <kinematic>0</kinematic>
      <gravity>1</gravity>
    </link>
    <joint name="rover_amalia_leg_shaft_f_l" type="revolute">
      <child>rover_amalia_leg_wheel_f_l</child>
      <parent>rover_amalia_leg_bar_f_l</parent>
      <axis>
        <xyz>0 1 0</xyz>
        <limit>
          <lower>-1e+16</lower>
          <upper>1e+16</upper>
        </limit>
        <use_parent_model_frame>1</use_parent_model_frame>
      </axis>
    </joint>
    <link name="rover_amalia_leg_bar_b_r">
      <pose>-0.13284 0.175 0.19 0 0 0</pose>
      <collision name="leg_bar_b_r_bar_collision">
        <geometry>
          <cylinder>
            <length>0.22</length>
            <radius>0.008</radius>
          </cylinder>
        </geometry>
        <max_contacts>10</max_contacts>
        <surface>
          <contact>
            <ode/>
          </contact>
          <bounce/>
          <friction>
            <ode/>
          </friction>
        </surface>
      </collision>
      <visual name="rover_amalia_leg_bar_b_r_bar_visual">
        <pose>0 0 0 0 0 0</pose>
        <geometry>
          <cylinder>
            <length>0.22</length>
            <radius>0.008</radius>
          </cylinder>
        </geometry>
      </visual>
    </link>
    <link name="rover_amalia_leg_wheel_b_r">
      <pose>-0.13284 0.219 0.08 0 0 0</pose>
      <inertial>
        <pose>0 0 0 0 0 0</pose>
        <mass>1</mass>
        <inertia>
          <ixx>100</ixx>
          <ixy>0</ixy>
          <ixz>0</ixz>
          <iyy>100</iyy>
          <iyz>0</iyz>
          <izz>100</izz>
        </inertia>
      </inertial>
      <collision name="rover_amalia_leg_wheel_b_r_collision">
        <pose>0 0 0 1.5707963 0 0</pose>
        <geometry>
          <cylinder>
            <length>0.07</length>
            <radius>0.08</radius>
          </cylinder>
        </geometry>
        <max_contacts>10</max_contacts>
      </collision>
      <visual name="rover_amalia_leg_wheel_b_r_visual">
        <pose>0 0 0 0 0 0</pose>
        <geometry>
          <mesh>
            <uri>model://rover_amalia_leg/meshes/wheel.dae</uri>
          </mesh>
        </geometry>
      </visual>
      <self_collide>0</self_collide>
      <kinematic>0</kinematic>
      <gravity>1</gravity>
    </link>
    <joint name="rover_amalia_leg_shaft_b_r" type="revolute">
      <child>rover_amalia_leg_wheel_b_r</child>
      <parent>rover_amalia_leg_bar_b_r</parent>
      <axis>
        <xyz>0 1 0</xyz>
        <limit>
          <lower>-1e+16</lower>
          <upper>1e+16</upper>
        </limit>
        <use_parent_model_frame>1</use_parent_model_frame>
      </axis>
    </joint>
    <link name="rover_amalia_leg_bar_b_l">
      <pose>-0.13284 -0.175 0.19 0 0 0</pose>
      <collision name="leg_bar_b_l_bar_collision">
        <geometry>
          <cylinder>
            <length>0.22</length>
            <radius>0.008</radius>
          </cylinder>
        </geometry>
        <max_contacts>10</max_contacts>
        <surface>
          <contact>
            <ode/>
          </contact>
          <bounce/>
          <friction>
            <ode/>
          </friction>
        </surface>
      </collision>
      <visual name="rover_amalia_leg_bar_b_l_bar_visual">
        <pose>0 0 0 0 0 0</pose>
        <geometry>
          <cylinder>
            <length>0.22</length>
            <radius>0.008</radius>
          </cylinder>
        </geometry>
      </visual>
    </link>
    <link name="rover_amalia_leg_wheel_b_l">
      <pose>-0.13284 -0.219 0.08 0 0 0</pose>
      <inertial>
        <pose>0 0 0 0 0 0</pose>
        <mass>1</mass>
        <inertia>
          <ixx>100</ixx>
          <ixy>0</ixy>
          <ixz>0</ixz>
          <iyy>100</iyy>
          <iyz>0</iyz>
          <izz>100</izz>
        </inertia>
      </inertial>
      <collision name="rover_amalia_leg_wheel_b_l_collision">
        <pose>0 0 0 1.5707963 0 0</pose>
        <geometry>
          <cylinder>
            <length>0.07</length>
            <radius>0.08</radius>
          </cylinder>
        </geometry>
        <max_contacts>10</max_contacts>
      </collision>
      <visual name="rover_amalia_leg_wheel_b_l_visual">
        <pose>0 0 0 0 0 0</pose>
        <geometry>
          <mesh>
            <uri>model://rover_amalia_leg/meshes/wheel.dae</uri>
          </mesh>
        </geometry>
      </visual>
      <self_collide>0</self_collide>
      <kinematic>0</kinematic>
      <gravity>1</gravity>
    </link>
    <joint name="rover_amalia_leg_shaft_b_l" type="revolute">
      <child>rover_amalia_leg_wheel_b_l</child>
      <parent>rover_amalia_leg_bar_b_l</parent>
      <axis>
        <xyz>0 1 0</xyz>
        <limit>
          <lower>-1e+16</lower>
          <upper>1e+16</upper>
        </limit>
        <use_parent_model_frame>1</use_parent_model_frame>
      </axis>
    </joint>
    <!--additional joints-->
    <joint name="rover_amalia_joint_chassis_leg_f_r" type="revolute">
      <child>rover_amalia_leg_bar_f_r</child>
      <parent>rover_amalia_chassis</parent>
      <axis>
        <xyz>0 1 0</xyz>
        <limit>
          <lower>-1e-16</lower>
          <upper>1e-16</upper>
        </limit>
        <dynamics/>
        <use_parent_model_frame>1</use_parent_model_frame>
      </axis>
    </joint>
    <joint name="rover_amalia_joint_chassis_leg_f_l" type="revolute">
      <child>rover_amalia_leg_bar_f_l</child>
      <parent>rover_amalia_chassis</parent>
      <axis>
        <xyz>0 1 0</xyz>
        <limit>
          <lower>-1e-16</lower>
          <upper>1e-16</upper>
        </limit>
        <dynamics/>
        <use_parent_model_frame>1</use_parent_model_frame>
      </axis>
    </joint>
    <joint name="rover_amalia_joint_chassis_leg_b_r" type="revolute">
      <child>rover_amalia_leg_bar_b_r</child>
      <parent>rover_amalia_chassis</parent>
      <axis>
        <xyz>0 1 0</xyz>
        <limit>
          <lower>-1e-16</lower>
          <upper>1e-16</upper>
        </limit>
        <dynamics/>
        <use_parent_model_frame>1</use_parent_model_frame>
      </axis>
    </joint>
    <joint name="rover_amalia_joint_chassis_leg_b_l" type="revolute">
      <child>rover_amalia_leg_bar_b_l</child>
      <parent>rover_amalia_chassis</parent>
      <axis>
        <xyz>0 1 0</xyz>
        <limit>
          <lower>-1e-16</lower>
          <upper>1e-16</upper>
        </limit>
        <dynamics/>
        <use_parent_model_frame>1</use_parent_model_frame>
      </axis>
    </joint>
    <joint name="rover_amalia_joint_turret_base_turret" type="revolute">
      <child>rover_amalia_turret_bar</child>
      <parent>rover_amalia_chassis</parent>
      <axis>
        <xyz>0 0 1</xyz>
        <limit>
          <lower>-1e-16</lower>
          <upper>1e-16</upper>
        </limit>
        <dynamics/>
        <use_parent_model_frame>1</use_parent_model_frame>
      </axis>
    </joint>
    <!--additional plugins-->
    <plugin filename="libgazebo_ros_skid_steer_drive.so" name="skid_steer_drive">
      <robotNamespace>rover_amalia</robotNamespace>
      <broadcastTF>1</broadcastTF>
      <rightFrontJoint>rover_amalia_leg_shaft_f_r</rightFrontJoint>
      <leftFrontJoint>rover_amalia_leg_shaft_f_l</leftFrontJoint>
      <rightRearJoint>rover_amalia_leg_shaft_b_r</rightRearJoint>
      <leftRearJoint>rover_amalia_leg_shaft_b_l</leftRearJoint>
      <wheelSeparation>0.492</wheelSeparation>
      <wheelDiameter>0.16</wheelDiameter>
      <torque>50.0</torque>
      <commandTopic>cmd_vel</commandTopic>
      <odometryTopic>odom</odometryTopic>
      <odometryFrame>odom</odometryFrame>
      <robotBaseFrame>base_footprint</robotBaseFrame>
      <updateRate>100.0</updateRate>
    </plugin>
  </model>
</sdf>

