<?xml version="1.0" ?>
<!-- =================================================================================== -->
<!-- |    This document was autogenerated by xacro from /home/clynamen/teamdiana/gazebo-assets/models/definitions/rover_amalia/model.xacro | -->
<!-- |    EDITING THIS FILE BY HAND IS NOT RECOMMENDED                                 | -->
<!-- =================================================================================== -->
<sdf version="1.5">
  <!--use sin function when available-->
  <model name="rover_amalia">
    <pose>0 0 0 0 0 0</pose>
    <static>0</static>
    <!--main components-->
    <link name="rover_amalia_turret_bar">
      <pose>0.195 0 0.464 0 0 0</pose>
      <!--<inertial>-->
      <!--<pose>0 0 0 0 0 0</pose>-->
      <!--<mass>0.78</mass>-->
      <!--<inertia>-->
      <!--<ixx>0.00000027555</ixx>-->
      <!--<ixy>0</ixy>-->
      <!--<ixz>0</ixz>-->
      <!--<iyy>0.00000027555</iyy>-->
      <!--<iyz>0</iyz>-->
      <!--<izz>0.00000027755</izz>-->
      <!--</inertia>-->
      <!--</inertial>-->
      <collision name="rover_amalia_turret_bar_collision">
        <pose>0 0 0.1 0 0 0</pose>
        <geometry>
          <cylinder>
            <length>0.2</length>
            <radius>0.01</radius>
          </cylinder>
        </geometry>
      </collision>
      <visual name="rover_amalia_turret_bar_visual">
        <pose>0 0 0.1 0 0 0</pose>
        <geometry>
          <mesh>
            <uri>model://rover_amalia_turret/meshes/turret-and-pan-base.dae</uri>
          </mesh>
        </geometry>
      </visual>
      <self_collide>0</self_collide>
      <kinematic>0</kinematic>
      <gravity>1</gravity>
    </link>
    <link name="rover_amalia_turret_tilt_base">
      <pose>0.195 0.015 0.717 0 0 0</pose>
      <!--correct inertial for pan base, use later-->
      <!--<inertial>-->
      <!--<pose>-0.00699 0.17952 0.02755 0 0 0</pose>-->
      <!--<mass>0.22386</mass>-->
      <!--<inertia>-->
      <!--<ixx>0.00010575745</ixx>-->
      <!--<ixy>0.00002524815</ixy>-->
      <!--<ixz>0</ixz>-->
      <!--<iyy>0.00100</iyy>-->
      <!--<iyz>0</iyz>-->
      <!--<izz>0.00021796864</izz>-->
      <!--</inertia>-->
      <!--</inertial>-->
      <!--this are ok, leave them:-->
      <!--<inertial>-->
      <!--<pose>0.012 -0.21853 0.02754  0 0 0</pose>-->
      <!--<pose>0 0 0 0 0 0</pose>-->
      <!--<mass>0.02786</mass>-->
      <!--<inertia>-->
      <!--<ixx>0.00002247622</ixx>-->
      <!--<ixy>0.</ixy>-->
      <!--<ixz>0</ixz>-->
      <!--<iyy>0.00001850151</iyy>-->
      <!--<iyz>0</iyz>-->
      <!--<izz>0.00000707185</izz>-->
      <!--</inertia>-->
      <!--</inertial>-->
      <visual name="rover_amalia_turret_tilt_base_visual">
        <pose>-0.016 -0.02 0.015 0 0 0</pose>
        <geometry>
          <mesh>
            <uri>model://rover_amalia_turret/meshes/pantilt_pan.dae</uri>
          </mesh>
        </geometry>
      </visual>
      <collision name="rover_amalia_turret_tilt_base_collision">
        <pose>-0.02 0 0.01 0 0 0</pose>
        <pose>0.195 -0.01 0.747 0 0 0</pose>
        <geometry>
          <box>
            <size>0.09 0.03 0.05 </size>
          </box>
        </geometry>
      </collision>
      <velocity_decay>
        <linear>0</linear>
        <angular>0</angular>
      </velocity_decay>
      <self_collide>0</self_collide>
      <kinematic>0</kinematic>
      <gravity>1</gravity>
    </link>
    <link name="rover_amalia_turret_tilt_hinge">
      <pose>0.195 -0.01 0.747 0 0 0</pose>
      <collision name="rover_amalia_turret_tilt_hinge_collision">
        <pose>0 0 0 0 0 0</pose>
        <pose>0.195 -0.01 0.747 0 0 0</pose>
        <geometry>
          <box>
            <size>0.03 0.07 0.04</size>
          </box>
        </geometry>
        <max_contacts>10</max_contacts>
        <surface>
          <contact>
            <ode/>
          </contact>
          <bounce/>
          <friction>
            <ode/>
          </friction>
        </surface>
      </collision>
      <visual name="rover_amalia_turret_tilt_hinge_visual">
        <pose>0 0 0 0 0 0</pose>
        <geometry>
          <mesh>
            <uri>model://rover_amalia_turret/meshes/pantilt_tilt.dae</uri>
          </mesh>
        </geometry>
      </visual>
      <visual name="rover_amalia_turret_camera_set_visual">
        <pose>0 0 0.052 0 0 0</pose>
        <geometry>
          <mesh>
            <uri>model://rover_amalia_turret/meshes/pantilt_payload.dae</uri>
          </mesh>
        </geometry>
      </visual>
      <sensor name="depth_camera" type="depth">
        <pose>0 0 0 0 0 0</pose>
        <camera>
          <horizontal_fov>0.767944</horizontal_fov>
          <image>
            <width>176</width>
            <height>144</height>
            <format>R8G8B8</format>
          </image>
          <clip>
            <near>0.8</near>
            <far>9</far>
          </clip>
        </camera>
        <plugin filename="libgazebo_ros_depth_camera.so" name="depth_camera_plugin">
          <alwaysOn>1</alwaysOn>
          <robotNamespace>rover_amalia</robotNamespace>
          <updateRate>25.0</updateRate>
          <imageTopicName>image_raw</imageTopicName>
          <depthImageTopicName>depth_raw</depthImageTopicName>
          <depthImageCameraInfoTopicName>camera_info</depthImageCameraInfoTopicName>
          <pointCloudTopicName>points</pointCloudTopicName>
          <cameraInfoTopicName>camera_info</cameraInfoTopicName>
          <cameraName>depth_cam</cameraName>
          <frameName>/base_link</frameName>
          <pointCloudCutoff>0.001</pointCloudCutoff>
          <distortionK1>0.0</distortionK1>
          <distortionK2>0.0</distortionK2>
          <distortionK3>0.0</distortionK3>
          <distortionT1>0.0</distortionT1>
          <distortionT2>0.0</distortionT2>
        </plugin>
        <always_on>true</always_on>
        <update_rate>25.0</update_rate>
      </sensor>
      <sensor name="camera" type="multicamera">
        <always_on>1</always_on>
        <update_rate>60</update_rate>
        <visualize>true</visualize>
        <camera name="left">
          <pose>0 0 0 0 0 0</pose>
          <horizontal_fov>1.047</horizontal_fov>
          <image>
            <width>1280</width>
            <height>1024</height>
          </image>
          <clip>
            <near>0.4</near>
            <far>100</far>
          </clip>
        </camera>
        <camera name="right">
          <pose>0 0 0 0 0 0</pose>
          <horizontal_fov>1.047</horizontal_fov>
          <image>
            <width>1280</width>
            <height>1024</height>
          </image>
          <clip>
            <near>0.4</near>
            <far>100</far>
          </clip>
        </camera>
        <plugin filename="libgazebo_ros_multicamera.so" name="stereo_camera_controller">
          <alwaysOn>true</alwaysOn>
          <updateRate>60.0</updateRate>
          <cameraName>stereo</cameraName>
          <imageTopicName>image_raw</imageTopicName>
          <cameraInfoTopicName>camera_info</cameraInfoTopicName>
          <frameName>left_camera_optical_frame</frameName>
          <rightFrameName>right_camera_optical_frame</rightFrameName>
          <hackBaseline>0.07</hackBaseline>
          <distortionK1>0.0</distortionK1>
          <distortionK2>0.0</distortionK2>
          <distortionK3>0.0</distortionK3>
          <distortionT1>0.0</distortionT1>
          <distortionT2>0.0</distortionT2>
        </plugin>
      </sensor>
      <velocity_decay>
        <linear>0</linear>
        <angular>0</angular>
      </velocity_decay>
      <self_collide>0</self_collide>
      <kinematic>0</kinematic>
      <gravity>1</gravity>
    </link>
    <joint name="rover_amalia_turret_pan" type="revolute">
      <child>rover_amalia_turret_tilt_base</child>
      <parent>rover_amalia_turret_bar</parent>
      <axis>
        <xyz>0 0 -1</xyz>
        <limit>
          <lower>-3.1415926</lower>
          <upper>3.1415926</upper>
        </limit>
      </axis>
      <physics>
        <ode>
          <cfm>0.0001</cfm>
          <erp>0.2</erp>
        </ode>
      </physics>
    </joint>
    <joint name="rover_amalia_turret_tilt" type="revolute">
      <child>rover_amalia_turret_tilt_hinge</child>
      <parent>rover_amalia_turret_tilt_base</parent>
      <axis>
        <xyz>0 -1 0</xyz>
        <limit>
          <lower>-2.35619445</lower>
          <upper>2.35619445</upper>
        </limit>
      </axis>
      <physics>
        <ode>
          <cfm>0</cfm>
          <erp>0.2</erp>
        </ode>
      </physics>
    </joint>
    <plugin filename="libgazebo_ros_joint_commander.so" name="joint_commander">
      <robotNamespace>rover_amalia</robotNamespace>
      <jointSet1>/ptu/cmd</jointSet1>
      <jointSet1Joint1>rover_amalia_turret_pan</jointSet1Joint1>
      <jointSet1Joint2>rover_amalia_turret_tilt</jointSet1Joint2>
    </plugin>
    <plugin filename="libgazebo_ros_joint_state_publisher.so" name="pan">
      <jointName>rover_amalia_turret_pan</jointName>
      <updateRate>30</updateRate>
    </plugin>
    <plugin filename="libgazebo_ros_joint_state_publisher.so" name="tilt">
      <jointName>rover_amalia_turret_tilt</jointName>
      <updateRate>30</updateRate>
    </plugin>
    <link name="rover_amalia_chassis">
      <pose>0 0 0.364 0 0 0</pose>
      <inertial>
        <pose>0.0216667 0 -0.0215556 0 -0 0</pose>
        <mass>15.6</mass>
        <inertia>
          <ixx>0.6385976</ixx>
          <ixy>0</ixy>
          <ixz>0</ixz>
          <iyy>0.521</iyy>
          <iyz>0</iyz>
          <izz>0.318954</izz>
        </inertia>
      </inertial>
      <visual name="rover_amalia_chassis_body_visual">
        <pose>0 0 0 0 0 0</pose>
        <geometry>
          <mesh>
            <uri>model://rover_amalia_chassis/meshes/chassis.dae</uri>
          </mesh>
        </geometry>
      </visual>
      <collision name="rover_amalia_chassis_body_collision">
        <pose>0 0 0 0 0 0</pose>
        <geometry>
          <box>
            <size>0.492 0.334 0.215</size>
          </box>
        </geometry>
        <max_contacts>10</max_contacts>
      </collision>
      <collision name="rover_amalia_chassis_turret_base_collision">
        <pose>0.195 0.05 0.073 0 0 0</pose>
        <geometry>
          <box>
            <size>0.089 0.064 0.046</size>
          </box>
        </geometry>
        <max_contacts>10</max_contacts>
      </collision>
      <visual name="rover_amalia_chassis_turret_base_visual">
        <pose>0.195 0.05 0.073 0 0 0</pose>
        <geometry>
          <box>
            <size>0.089 0.064 0.046</size>
          </box>
        </geometry>
      </visual>
      <visual name="rover_amalia_chassis_front_up_rangefinder_visual">
        <pose>0.246 0 -0.05 0 -0 0</pose>
        <geometry>
          <box>
            <size>0.01 0.03 0.01</size>
          </box>
        </geometry>
      </visual>
      <visual name="rover_amalia_chassis_front_down_rangefinder_visual">
        <pose>0.236 0 -0.06 0 1.57 0</pose>
        <geometry>
          <box>
            <size>0.01 0.03 0.01</size>
          </box>
        </geometry>
      </visual>
      <sensor name="range_front_down_ray" type="ray">
        <pose>0.25 0 -0.09 0 1.5707963 0</pose>
        <ray>
          <scan>
            <horizontal>
              <!-- could be just 1, but with 10 it is visualized in the gui-->
              <samples>20</samples>
              <resolution>1.0</resolution>
              <min_angle>-0.02</min_angle>
              <max_angle>0.02</max_angle>
            </horizontal>
          </scan>
          <range>
            <min>0.15</min>
            <max>3</max>
          </range>
        </ray>
        <!-- test plugin -->
        <plugin filename="libgazebo_ros_range_finder.so" name="plugin_1">
          <gaussianNoise>0.005</gaussianNoise>
          <alwaysOn>true</alwaysOn>
          <updateRate>20</updateRate>
          <topicName>/ADC/range_front_down</topicName>
          <frameName>base_link</frameName>
        </plugin>
        <always_on>true</always_on>
        <update_rate>2.0</update_rate>
        <visualize>true</visualize>
      </sensor>
      <visual name="rover_amalia_chassis_rear_up_rangefinder_visual">
        <pose>-0.246 0 -0.05 3.14159 0.00159265 3.14159</pose>
        <geometry>
          <box>
            <size>0.01 0.03 0.01</size>
          </box>
        </geometry>
      </visual>
      <visual name="rover_amalia_chassis_rear_down_rangefinder_visual">
        <pose>-0.236 0 -0.06 0 1.57 0</pose>
        <geometry>
          <box>
            <size>0.01 0.03 0.01</size>
          </box>
        </geometry>
      </visual>
      <sensor name="range_rear_down_ray" type="ray">
        <pose>-0.238 0 -0.06 0 1.57 0</pose>
        <ray>
          <scan>
            <horizontal>
              <!-- could be just 1, but with 10 it is visualized in the gui-->
              <samples>20</samples>
              <resolution>1.0</resolution>
              <min_angle>-0.02</min_angle>
              <max_angle>0.02</max_angle>
            </horizontal>
          </scan>
          <range>
            <min>0.15</min>
            <max>3</max>
          </range>
        </ray>
        <!-- test plugin -->
        <plugin filename="libgazebo_ros_range_finder.so" name="plugin_1">
          <gaussianNoise>0.005</gaussianNoise>
          <alwaysOn>true</alwaysOn>
          <updateRate>20</updateRate>
          <topicName>/ADC/range_rear_down</topicName>
          <frameName>base_link</frameName>
        </plugin>
        <always_on>true</always_on>
        <update_rate>2.0</update_rate>
        <visualize>true</visualize>
      </sensor>
      <self_collide>0</self_collide>
      <kinematic>0</kinematic>
      <gravity>1</gravity>
    </link>
    <link name="rover_amalia_leg_bar_f_r">
      <pose>0.13776 0.175 0.2 0 0 0</pose>
      <inertial>
        <pose>0 0 0 0 0 0</pose>
        <mass>0.31</mass>
        <inertia>
          <ixx>0.00279048</ixx>
          <ixy>0</ixy>
          <ixz>-0.00003956</ixz>
          <iyy>0.00275062</iyy>
          <iyz>0</iyz>
          <izz>0.00008316</izz>
        </inertia>
      </inertial>
      <collision name="leg_bar_f_r_bar_collision">
        <geometry>
          <cylinder>
            <length>0.22</length>
            <radius>0.008</radius>
          </cylinder>
        </geometry>
        <max_contacts>10</max_contacts>
        <surface>
          <contact>
            <ode/>
          </contact>
          <bounce/>
          <friction>
            <ode/>
          </friction>
        </surface>
      </collision>
      <visual name="rover_amalia_leg_bar_f_r_bar_visual">
        <pose>0 0 0 0 0 0</pose>
        <geometry>
          <cylinder>
            <length>0.22</length>
            <radius>0.008</radius>
          </cylinder>
        </geometry>
      </visual>
    </link>
    <link name="rover_amalia_leg_wheel_f_r">
      <pose>0.13776 0.219 0.09 0 0 0</pose>
      <inertial>
        <pose>0 0 0 0 0 0</pose>
        <mass>1.1</mass>
        <inertia>
          <ixx>0.00353418</ixx>
          <iyy>0.00222499</iyy>
          <izz>0.00222713</izz>
          <ixy>0</ixy>
          <ixz>0</ixz>
          <iyz>0</iyz>
        </inertia>
      </inertial>
      <collision name="rover_amalia_leg_wheel_f_r_collision">
        <pose>0 0 0 1.5707963 0 0</pose>
        <geometry>
          <cylinder>
            <length>0.07</length>
            <radius>0.09</radius>
          </cylinder>
        </geometry>
        <max_contacts>10</max_contacts>
      </collision>
      <visual name="rover_amalia_leg_wheel_f_r_visual">
        <pose>0 0 0 0 0 0</pose>
        <geometry>
          <mesh>
            <uri>model://rover_amalia_leg/meshes/wheel.dae</uri>
          </mesh>
        </geometry>
      </visual>
      <self_collide>0</self_collide>
      <kinematic>0</kinematic>
      <gravity>1</gravity>
    </link>
    <joint name="rover_amalia_leg_shaft_f_r" type="revolute">
      <child>rover_amalia_leg_wheel_f_r</child>
      <parent>rover_amalia_leg_bar_f_r</parent>
      <axis>
        <xyz>0 1 0</xyz>
        <limit>
          <lower>-1e+16</lower>
          <upper>1e+16</upper>
        </limit>
        <use_parent_model_frame>1</use_parent_model_frame>
      </axis>
    </joint>
    <plugin filename="libgazebo_ros_joint_state_publisher.so" name="wheel_f_r">
      <jointName>rover_amalia_leg_shaft_f_r</jointName>
      <updateRate>30</updateRate>
    </plugin>
    <link name="rover_amalia_leg_bar_f_l">
      <pose>0.13776 -0.175 0.2 0 0 0</pose>
      <inertial>
        <pose>0 0 0 0 0 0</pose>
        <mass>0.31</mass>
        <inertia>
          <ixx>0.00279048</ixx>
          <ixy>0</ixy>
          <ixz>-0.00003956</ixz>
          <iyy>0.00275062</iyy>
          <iyz>0</iyz>
          <izz>0.00008316</izz>
        </inertia>
      </inertial>
      <collision name="leg_bar_f_l_bar_collision">
        <geometry>
          <cylinder>
            <length>0.22</length>
            <radius>0.008</radius>
          </cylinder>
        </geometry>
        <max_contacts>10</max_contacts>
        <surface>
          <contact>
            <ode/>
          </contact>
          <bounce/>
          <friction>
            <ode/>
          </friction>
        </surface>
      </collision>
      <visual name="rover_amalia_leg_bar_f_l_bar_visual">
        <pose>0 0 0 0 0 0</pose>
        <geometry>
          <cylinder>
            <length>0.22</length>
            <radius>0.008</radius>
          </cylinder>
        </geometry>
      </visual>
    </link>
    <link name="rover_amalia_leg_wheel_f_l">
      <pose>0.13776 -0.219 0.09 0 0 0</pose>
      <inertial>
        <pose>0 0 0 0 0 0</pose>
        <mass>1.1</mass>
        <inertia>
          <ixx>0.00353418</ixx>
          <iyy>0.00222499</iyy>
          <izz>0.00222713</izz>
          <ixy>0</ixy>
          <ixz>0</ixz>
          <iyz>0</iyz>
        </inertia>
      </inertial>
      <collision name="rover_amalia_leg_wheel_f_l_collision">
        <pose>0 0 0 1.5707963 0 0</pose>
        <geometry>
          <cylinder>
            <length>0.07</length>
            <radius>0.09</radius>
          </cylinder>
        </geometry>
        <max_contacts>10</max_contacts>
      </collision>
      <visual name="rover_amalia_leg_wheel_f_l_visual">
        <pose>0 0 0 0 0 0</pose>
        <geometry>
          <mesh>
            <uri>model://rover_amalia_leg/meshes/wheel.dae</uri>
          </mesh>
        </geometry>
      </visual>
      <self_collide>0</self_collide>
      <kinematic>0</kinematic>
      <gravity>1</gravity>
    </link>
    <joint name="rover_amalia_leg_shaft_f_l" type="revolute">
      <child>rover_amalia_leg_wheel_f_l</child>
      <parent>rover_amalia_leg_bar_f_l</parent>
      <axis>
        <xyz>0 1 0</xyz>
        <limit>
          <lower>-1e+16</lower>
          <upper>1e+16</upper>
        </limit>
        <use_parent_model_frame>1</use_parent_model_frame>
      </axis>
    </joint>
    <plugin filename="libgazebo_ros_joint_state_publisher.so" name="wheel_f_l">
      <jointName>rover_amalia_leg_shaft_f_l</jointName>
      <updateRate>30</updateRate>
    </plugin>
    <link name="rover_amalia_leg_bar_b_r">
      <pose>-0.13776 0.175 0.2 0 0 0</pose>
      <inertial>
        <pose>0 0 0 0 0 0</pose>
        <mass>0.31</mass>
        <inertia>
          <ixx>0.00279048</ixx>
          <ixy>0</ixy>
          <ixz>-0.00003956</ixz>
          <iyy>0.00275062</iyy>
          <iyz>0</iyz>
          <izz>0.00008316</izz>
        </inertia>
      </inertial>
      <collision name="leg_bar_b_r_bar_collision">
        <geometry>
          <cylinder>
            <length>0.22</length>
            <radius>0.008</radius>
          </cylinder>
        </geometry>
        <max_contacts>10</max_contacts>
        <surface>
          <contact>
            <ode/>
          </contact>
          <bounce/>
          <friction>
            <ode/>
          </friction>
        </surface>
      </collision>
      <visual name="rover_amalia_leg_bar_b_r_bar_visual">
        <pose>0 0 0 0 0 0</pose>
        <geometry>
          <cylinder>
            <length>0.22</length>
            <radius>0.008</radius>
          </cylinder>
        </geometry>
      </visual>
    </link>
    <link name="rover_amalia_leg_wheel_b_r">
      <pose>-0.13776 0.219 0.09 0 0 0</pose>
      <inertial>
        <pose>0 0 0 0 0 0</pose>
        <mass>1.1</mass>
        <inertia>
          <ixx>0.00353418</ixx>
          <iyy>0.00222499</iyy>
          <izz>0.00222713</izz>
          <ixy>0</ixy>
          <ixz>0</ixz>
          <iyz>0</iyz>
        </inertia>
      </inertial>
      <collision name="rover_amalia_leg_wheel_b_r_collision">
        <pose>0 0 0 1.5707963 0 0</pose>
        <geometry>
          <cylinder>
            <length>0.07</length>
            <radius>0.09</radius>
          </cylinder>
        </geometry>
        <max_contacts>10</max_contacts>
      </collision>
      <visual name="rover_amalia_leg_wheel_b_r_visual">
        <pose>0 0 0 0 0 0</pose>
        <geometry>
          <mesh>
            <uri>model://rover_amalia_leg/meshes/wheel.dae</uri>
          </mesh>
        </geometry>
      </visual>
      <self_collide>0</self_collide>
      <kinematic>0</kinematic>
      <gravity>1</gravity>
    </link>
    <joint name="rover_amalia_leg_shaft_b_r" type="revolute">
      <child>rover_amalia_leg_wheel_b_r</child>
      <parent>rover_amalia_leg_bar_b_r</parent>
      <axis>
        <xyz>0 1 0</xyz>
        <limit>
          <lower>-1e+16</lower>
          <upper>1e+16</upper>
        </limit>
        <use_parent_model_frame>1</use_parent_model_frame>
      </axis>
    </joint>
    <plugin filename="libgazebo_ros_joint_state_publisher.so" name="wheel_b_r">
      <jointName>rover_amalia_leg_shaft_b_r</jointName>
      <updateRate>30</updateRate>
    </plugin>
    <link name="rover_amalia_leg_bar_b_l">
      <pose>-0.13776 -0.175 0.2 0 0 0</pose>
      <inertial>
        <pose>0 0 0 0 0 0</pose>
        <mass>0.31</mass>
        <inertia>
          <ixx>0.00279048</ixx>
          <ixy>0</ixy>
          <ixz>-0.00003956</ixz>
          <iyy>0.00275062</iyy>
          <iyz>0</iyz>
          <izz>0.00008316</izz>
        </inertia>
      </inertial>
      <collision name="leg_bar_b_l_bar_collision">
        <geometry>
          <cylinder>
            <length>0.22</length>
            <radius>0.008</radius>
          </cylinder>
        </geometry>
        <max_contacts>10</max_contacts>
        <surface>
          <contact>
            <ode/>
          </contact>
          <bounce/>
          <friction>
            <ode/>
          </friction>
        </surface>
      </collision>
      <visual name="rover_amalia_leg_bar_b_l_bar_visual">
        <pose>0 0 0 0 0 0</pose>
        <geometry>
          <cylinder>
            <length>0.22</length>
            <radius>0.008</radius>
          </cylinder>
        </geometry>
      </visual>
    </link>
    <link name="rover_amalia_leg_wheel_b_l">
      <pose>-0.13776 -0.219 0.09 0 0 0</pose>
      <inertial>
        <pose>0 0 0 0 0 0</pose>
        <mass>1.1</mass>
        <inertia>
          <ixx>0.00353418</ixx>
          <iyy>0.00222499</iyy>
          <izz>0.00222713</izz>
          <ixy>0</ixy>
          <ixz>0</ixz>
          <iyz>0</iyz>
        </inertia>
      </inertial>
      <collision name="rover_amalia_leg_wheel_b_l_collision">
        <pose>0 0 0 1.5707963 0 0</pose>
        <geometry>
          <cylinder>
            <length>0.07</length>
            <radius>0.09</radius>
          </cylinder>
        </geometry>
        <max_contacts>10</max_contacts>
      </collision>
      <visual name="rover_amalia_leg_wheel_b_l_visual">
        <pose>0 0 0 0 0 0</pose>
        <geometry>
          <mesh>
            <uri>model://rover_amalia_leg/meshes/wheel.dae</uri>
          </mesh>
        </geometry>
      </visual>
      <self_collide>0</self_collide>
      <kinematic>0</kinematic>
      <gravity>1</gravity>
    </link>
    <joint name="rover_amalia_leg_shaft_b_l" type="revolute">
      <child>rover_amalia_leg_wheel_b_l</child>
      <parent>rover_amalia_leg_bar_b_l</parent>
      <axis>
        <xyz>0 1 0</xyz>
        <limit>
          <lower>-1e+16</lower>
          <upper>1e+16</upper>
        </limit>
        <use_parent_model_frame>1</use_parent_model_frame>
      </axis>
    </joint>
    <plugin filename="libgazebo_ros_joint_state_publisher.so" name="wheel_b_l">
      <jointName>rover_amalia_leg_shaft_b_l</jointName>
      <updateRate>30</updateRate>
    </plugin>
    <!--additional joints-->
    <joint name="rover_amalia_joint_chassis_leg_f_r" type="revolute">
      <pose>0 0 0.11 0 0 0</pose>
      <child>rover_amalia_leg_bar_f_r</child>
      <parent>rover_amalia_chassis</parent>
      <axis>
        <xyz>0 1 0</xyz>
        <!--<dynamics>-->
        <!--<damping>0.0001</damping>-->
        <!--<spring_stiffness>1</spring_stiffness>-->
        <!--<spring_reference>0</spring_reference>-->
        <!--</dynamics>-->
        <use_parent_model_frame>1</use_parent_model_frame>
      </axis>
      <physics>
        <ode>
          <provide_feedback>1</provide_feedback>
        </ode>
        <provide_feedback>1</provide_feedback>
      </physics>
    </joint>
    <plugin filename="libgazebo_ros_dynamixel_motor.so" name="dynamixel_motor">
      <joint>rover_amalia_joint_chassis_leg_f_r</joint>
      <base_topic_name>motore_1_controller</base_topic_name>
      <default_pos>-2.0</default_pos>
      <default_torque_limit>100000</default_torque_limit>
      <reduction_value>6.3</reduction_value>
    </plugin>
    <plugin filename="libgazebo_ros_joint_state_publisher.so" name="arm_f_r">
      <jointName>rover_amalia_joint_chassis_leg_f_r</jointName>
      <updateRate>30</updateRate>
    </plugin>
    <joint name="rover_amalia_joint_chassis_leg_f_l" type="revolute">
      <pose>0 0 0.11 0 0 0</pose>
      <child>rover_amalia_leg_bar_f_l</child>
      <parent>rover_amalia_chassis</parent>
      <axis>
        <xyz>0 1 0</xyz>
        <!--<dynamics>-->
        <!--<damping>0.0001</damping>-->
        <!--<spring_stiffness>1</spring_stiffness>-->
        <!--<spring_reference>0</spring_reference>-->
        <!--</dynamics>-->
        <use_parent_model_frame>1</use_parent_model_frame>
      </axis>
      <physics>
        <ode>
          <provide_feedback>1</provide_feedback>
        </ode>
        <provide_feedback>1</provide_feedback>
      </physics>
    </joint>
    <plugin filename="libgazebo_ros_dynamixel_motor.so" name="dynamixel_motor">
      <joint>rover_amalia_joint_chassis_leg_f_l</joint>
      <base_topic_name>motore_2_controller</base_topic_name>
      <default_pos>-2.0</default_pos>
      <default_torque_limit>100000</default_torque_limit>
      <reduction_value>6.3</reduction_value>
    </plugin>
    <plugin filename="libgazebo_ros_joint_state_publisher.so" name="arm_f_l">
      <jointName>rover_amalia_joint_chassis_leg_f_l</jointName>
      <updateRate>30</updateRate>
    </plugin>
    <joint name="rover_amalia_joint_chassis_leg_b_r" type="revolute">
      <pose>0 0 0.11 0 0 0</pose>
      <child>rover_amalia_leg_bar_b_r</child>
      <parent>rover_amalia_chassis</parent>
      <axis>
        <xyz>0 1 0</xyz>
        <!--<dynamics>-->
        <!--<damping>0.0001</damping>-->
        <!--<spring_stiffness>1</spring_stiffness>-->
        <!--<spring_reference>0</spring_reference>-->
        <!--</dynamics>-->
        <use_parent_model_frame>1</use_parent_model_frame>
      </axis>
      <physics>
        <ode>
          <provide_feedback>1</provide_feedback>
        </ode>
        <provide_feedback>1</provide_feedback>
      </physics>
    </joint>
    <plugin filename="libgazebo_ros_dynamixel_motor.so" name="dynamixel_motor">
      <joint>rover_amalia_joint_chassis_leg_b_r</joint>
      <base_topic_name>motore_3_controller</base_topic_name>
      <default_pos>2.0</default_pos>
      <default_torque_limit>100000</default_torque_limit>
      <reduction_value>6.3</reduction_value>
    </plugin>
    <plugin filename="libgazebo_ros_joint_state_publisher.so" name="arm_b_r">
      <jointName>rover_amalia_joint_chassis_leg_b_r</jointName>
      <updateRate>30</updateRate>
    </plugin>
    <joint name="rover_amalia_joint_chassis_leg_b_l" type="revolute">
      <pose>0 0 0.11 0 0 0</pose>
      <child>rover_amalia_leg_bar_b_l</child>
      <parent>rover_amalia_chassis</parent>
      <axis>
        <xyz>0 1 0</xyz>
        <!--<dynamics>-->
        <!--<damping>0.0001</damping>-->
        <!--<spring_stiffness>1</spring_stiffness>-->
        <!--<spring_reference>0</spring_reference>-->
        <!--</dynamics>-->
        <use_parent_model_frame>1</use_parent_model_frame>
      </axis>
      <physics>
        <ode>
          <provide_feedback>1</provide_feedback>
        </ode>
        <provide_feedback>1</provide_feedback>
      </physics>
    </joint>
    <plugin filename="libgazebo_ros_dynamixel_motor.so" name="dynamixel_motor">
      <joint>rover_amalia_joint_chassis_leg_b_l</joint>
      <base_topic_name>motore_4_controller</base_topic_name>
      <default_pos>2.0</default_pos>
      <default_torque_limit>100000</default_torque_limit>
      <reduction_value>6.3</reduction_value>
    </plugin>
    <plugin filename="libgazebo_ros_joint_state_publisher.so" name="arm_b_l">
      <jointName>rover_amalia_joint_chassis_leg_b_l</jointName>
      <updateRate>30</updateRate>
    </plugin>
    <joint name="rover_amalia_joint_turret_base_turret" type="revolute">
      <child>rover_amalia_turret_bar</child>
      <parent>rover_amalia_chassis</parent>
      <axis>
        <xyz>0 0 1</xyz>
        <limit>
          <lower>-1e-16</lower>
          <upper>1e-16</upper>
        </limit>
        <dynamics/>
        <use_parent_model_frame>1</use_parent_model_frame>
      </axis>
    </joint>
    <!--additional plugins-->
    <plugin filename="libgazebo_ros_skid_steer_drive.so" name="skid_steer_drive">
      <robotNamespace>rover_amalia</robotNamespace>
      <broadcastTF>1</broadcastTF>
      <rightFrontJoint>rover_amalia_leg_shaft_f_r</rightFrontJoint>
      <leftFrontJoint>rover_amalia_leg_shaft_f_l</leftFrontJoint>
      <rightRearJoint>rover_amalia_leg_shaft_b_r</rightRearJoint>
      <leftRearJoint>rover_amalia_leg_shaft_b_l</leftRearJoint>
      <wheelSeparation>0.492</wheelSeparation>
      <wheelDiameter>0.18</wheelDiameter>
      <torque>50.0</torque>
      <commandTopic>cmd_vel</commandTopic>
      <odometryTopic>odom</odometryTopic>
      <odometryFrame>odom</odometryFrame>
      <robotBaseFrame>base_footprint</robotBaseFrame>
      <updateRate>100.0</updateRate>
    </plugin>
  </model>
</sdf>

