<?xml version="1.0" ?>
<!-- =================================================================================== -->
<!-- |    This document was autogenerated by xacro from /home/clynamen/teamdiana/gazebo-assets/models/definitions/rover_amalia_turret/model.xacro | -->
<!-- |    EDITING THIS FILE BY HAND IS NOT RECOMMENDED                                 | -->
<!-- =================================================================================== -->
<sdf version="1.5">
  <model name="rover_amalia_turret">
    <link name="rover_amalia_turret_bar">
      <pose>0 0 0 0 0 0</pose>
      <inertial>
        <pose>0 0 0 0 0 0</pose>
        <mass>1</mass>
        <inertia>
          <ixx>100</ixx>
          <ixy>0</ixy>
          <ixz>0</ixz>
          <iyy>100</iyy>
          <iyz>0</iyz>
          <izz>100</izz>
        </inertia>
      </inertial>
      <collision name="rover_amalia_turret_bar_collision">
        <pose>0 0 0.1 0 0 0</pose>
        <geometry>
          <cylinder>
            <length>0.2</length>
            <radius>0.01</radius>
          </cylinder>
        </geometry>
      </collision>
      <visual name="rover_amalia_turret_bar_visual">
        <pose>0 0 0.1 0 0 0</pose>
        <geometry>
          <cylinder>
            <length>0.2</length>
            <radius>0.01</radius>
          </cylinder>
        </geometry>
      </visual>
      <self_collide>0</self_collide>
      <kinematic>0</kinematic>
      <gravity>1</gravity>
    </link>
    <link name="rover_amalia_turret_pan_base">
      <pose>0 0 0.21 0 0 0</pose>
      <inertial>
        <pose>0 0 0 0 0 0</pose>
        <mass>1</mass>
        <inertia>
          <ixx>100</ixx>
          <ixy>0</ixy>
          <ixz>0</ixz>
          <iyy>100</iyy>
          <iyz>0</iyz>
          <izz>100</izz>
        </inertia>
      </inertial>
      <visual name="rover_amalia_turret_pan_base_visual">
        <pose>-0.016 -0.02 0.015 0 0 0</pose>
        <geometry>
          <mesh>
            <uri>model://rover_amalia_turret/meshes/pantilt_pan.dae</uri>
          </mesh>
        </geometry>
      </visual>
      <velocity_decay>
        <linear>0</linear>
        <angular>0</angular>
      </velocity_decay>
      <self_collide>0</self_collide>
      <kinematic>0</kinematic>
      <gravity>1</gravity>
    </link>
    <link name="rover_amalia_turret_tilt_base">
      <pose>0 -0.01 0.24 0 0 0</pose>
      <inertial>
        <pose>0 0 0 0 0 0</pose>
        <mass>2</mass>
        <inertia>
          <ixx>200.001</ixx>
          <ixy>0</ixy>
          <ixz>0</ixz>
          <iyy>200.001</iyy>
          <iyz>0</iyz>
          <izz>200</izz>
        </inertia>
      </inertial>
      <collision name="rover_amalia_turret_tilt_base_collision">
        <pose>0 0 0 0 0 0</pose>
        <pose>0 -0.01 0.24 0 0 0</pose>
        <geometry>
          <box>
            <size>0.06 0.02 0.04</size>
          </box>
        </geometry>
        <max_contacts>10</max_contacts>
        <surface>
          <contact>
            <ode/>
          </contact>
          <bounce/>
          <friction>
            <ode/>
          </friction>
        </surface>
      </collision>
      <visual name="rover_amalia_turret_tilt_base_visual">
        <pose>0 0 0 0 0 0</pose>
        <geometry>
          <mesh>
            <uri>model://rover_amalia_turret/meshes/pantilt_tilt.dae</uri>
          </mesh>
        </geometry>
      </visual>
      <visual name="rover_amalia_turret_camera_set_visual">
        <pose>0 0 0.052 0 0 0</pose>
        <geometry>
          <mesh>
            <uri>model://rover_amalia_turret/meshes/pantilt_payload.dae</uri>
          </mesh>
        </geometry>
      </visual>
      <sensor name="depth_camera" type="depth">
        <pose>0 0 0 0 0 0</pose>
        <camera>
          <horizontal_fov>1.578</horizontal_fov>
          <image>
            <width>640</width>
            <height>480</height>
            <format>R8G8B8</format>
          </image>
          <clip>
            <near>0.4</near>
            <far>100</far>
          </clip>
        </camera>
        <plugin filename="libgazebo_ros_depth_camera.so" name="depth_camera_plugin">
          <alwaysOn>1</alwaysOn>
          <robotNamespace>rover_amalia</robotNamespace>
          <updateRate>10.0</updateRate>
          <imageTopicName>image_raw</imageTopicName>
          <depthImageTopicName>depth_raw</depthImageTopicName>
          <depthImageCameraInfoTopicName>camera_info</depthImageCameraInfoTopicName>
          <pointCloudTopicName>points</pointCloudTopicName>
          <cameraInfoTopicName>camera_info</cameraInfoTopicName>
          <cameraName>depth_cam</cameraName>
          <frameName>/base_link</frameName>
          <pointCloudCutoff>0.001</pointCloudCutoff>
          <distortionK1>0.0</distortionK1>
          <distortionK2>0.0</distortionK2>
          <distortionK3>0.0</distortionK3>
          <distortionT1>0.0</distortionT1>
          <distortionT2>0.0</distortionT2>
        </plugin>
        <always_on>true</always_on>
        <update_rate>10.0</update_rate>
      </sensor>
      <sensor name="camera" type="multicamera">
        <always_on>1</always_on>
        <update_rate>30</update_rate>
        <visualize>true</visualize>
        <camera name="left">
          <pose>0 0 0 0 0 0</pose>
          <horizontal_fov>1.047</horizontal_fov>
          <image>
            <width>320</width>
            <height>240</height>
          </image>
          <clip>
            <near>0.4</near>
            <far>100</far>
          </clip>
        </camera>
        <camera name="right">
          <pose>0 0 0 0 0 0</pose>
          <horizontal_fov>1.047</horizontal_fov>
          <image>
            <width>320</width>
            <height>240</height>
          </image>
          <clip>
            <near>0.4</near>
            <far>100</far>
          </clip>
        </camera>
        <plugin filename="libgazebo_ros_multicamera.so" name="stereo_camera_controller">
          <alwaysOn>true</alwaysOn>
          <updateRate>0.0</updateRate>
          <cameraName>camera</cameraName>
          <imageTopicName>image_raw</imageTopicName>
          <cameraInfoTopicName>camera_info</cameraInfoTopicName>
          <frameName>left_camera_optical_frame</frameName>
          <!--<rightFrameName>right_camera_optical_frame</rightFrameName>-->
          <hackBaseline>0.07</hackBaseline>
          <distortionK1>0.0</distortionK1>
          <distortionK2>0.0</distortionK2>
          <distortionK3>0.0</distortionK3>
          <distortionT1>0.0</distortionT1>
          <distortionT2>0.0</distortionT2>
        </plugin>
      </sensor>
      <velocity_decay>
        <linear>0</linear>
        <angular>0</angular>
      </velocity_decay>
      <self_collide>0</self_collide>
      <kinematic>0</kinematic>
      <gravity>1</gravity>
    </link>
    <joint name="rover_amalia_turret_pan" type="revolute">
      <child>rover_amalia_turret_pan_base</child>
      <parent>rover_amalia_turret_bar</parent>
      <axis>
        <xyz>0 0 -1</xyz>
        <limit>
          <lower>-3.1415926</lower>
          <upper>3.1415926</upper>
        </limit>
        <dynamics/>
      </axis>
    </joint>
    <joint name="rover_amalia_turret_tilt" type="revolute">
      <child>rover_amalia_turret_tilt_base</child>
      <parent>rover_amalia_turret_pan_base</parent>
      <axis>
        <xyz>0 -1 0</xyz>
        <limit>
          <lower>-2.35619445</lower>
          <upper>2.35619445</upper>
        </limit>
        <dynamics/>
      </axis>
    </joint>
    <plugin filename="libgazebo_ros_joint_commander.so" name="joint_commander">
      <robotNamespace>rover_amalia</robotNamespace>
      <jointSet1>/ptu/cmd</jointSet1>
      <jointSet1Joint1>rover_amalia_turret_pan</jointSet1Joint1>
      <jointSet1Joint2>rover_amalia_turret_tilt</jointSet1Joint2>
    </plugin>
    <pose>0 0 0 0 0 0</pose>
  </model>
</sdf>

