<?xml version="1.0" ?>
<!-- =================================================================================== -->
<!-- |    This document was autogenerated by xacro from /home/clynamen/teamdiana/gazebo-assets/models/definitions/rover_amalia_turret/model.xacro | -->
<!-- |    EDITING THIS FILE BY HAND IS NOT RECOMMENDED                                 | -->
<!-- =================================================================================== -->
<sdf version="1.5">
  <model name="rover_amalia_turret">
    <link name="rover_amalia_turret_bar">
      <pose>0 0 0 0 0 0</pose>
      <collision name="rover_amalia_turret_bar_collision">
        <pose>0 0 0.1 0 0 0</pose>
        <geometry>
          <cylinder>
            <length>0.2</length>
            <radius>0.01</radius>
          </cylinder>
        </geometry>
      </collision>
      <visual name="rover_amalia_turret_bar_visual">
        <pose>0 0 0.1 0 0 0</pose>
        <geometry>
          <mesh>
            <uri>model://rover_amalia_turret/meshes/turret.dae</uri>
          </mesh>
        </geometry>
        <material>
          <diffuse>0.4 0.4 0.4 1</diffuse>
          <specular>1 1 1 1</specular>
        </material>
      </visual>
      <visual name="rover_amalia_turret_bar_pan_base_visual">
        <pose>-0.012 -0.007 0.215 0 0 0</pose>
        <geometry>
          <mesh>
            <uri>model://rover_amalia_turret/meshes/pan_base.dae</uri>
          </mesh>
        </geometry>
        <material>
          <ambient>0.3 0.3 0.3 1</ambient>
          <diffuse>0.1 0.1 0.1 1</diffuse>
          <specular>1 1 1 1</specular>
        </material>
      </visual>
      <self_collide>0</self_collide>
      <kinematic>0</kinematic>
      <gravity>0</gravity>
      <inertial>
        <mass>0.000001</mass>
      </inertial>
    </link>
    <link name="rover_amalia_turret_tilt_base">
      <pose>0 0.015 0.253 0 0 0</pose>
      <visual name="rover_amalia_turret_tilt_base_visual">
        <pose>-0.020 -0.025 0.015 0 0 0</pose>
        <geometry>
          <mesh>
            <uri>model://rover_amalia_turret/meshes/pantilt_pan.dae</uri>
          </mesh>
        </geometry>
        <material>
          <ambient>0.3 0.3 0.3 1</ambient>
          <diffuse>0.1 0.1 0.1 1</diffuse>
          <specular>1 1 1 1</specular>
        </material>
      </visual>
      <collision name="rover_amalia_turret_tilt_base_collision">
        <pose>-0.02 -0.025 0.01 0 0 0</pose>
        <pose>0 0 0.283 0 0 0</pose>
        <geometry>
          <box>
            <size>0.09 0.03 0.05 </size>
          </box>
        </geometry>
      </collision>
      <velocity_decay>
        <linear>0</linear>
        <angular>0</angular>
      </velocity_decay>
      <self_collide>0</self_collide>
      <kinematic>0</kinematic>
      <gravity>0</gravity>
      <inertial>
        <mass>0.000001</mass>
      </inertial>
    </link>
    <link name="rover_amalia_turret_tilt_hinge">
      <pose>0 0 0.283 0 0 0</pose>
      <collision name="rover_amalia_turret_tilt_hinge_collision">
        <pose>0 0 0 0 0 0</pose>
        <pose>0 0 0.283 0 0 0</pose>
        <geometry>
          <box>
            <size>0.03 0.07 0.04</size>
          </box>
        </geometry>
        <max_contacts>10</max_contacts>
      </collision>
      <visual name="rover_amalia_turret_tilt_hinge_visual">
        <pose>0 0 0 0 0 0</pose>
        <geometry>
          <mesh>
            <uri>model://rover_amalia_turret/meshes/pantilt_tilt.dae</uri>
          </mesh>
        </geometry>
        <material>
          <ambient>0.3 0.3 0.3 1</ambient>
          <diffuse>0.1 0.1 0.1 1</diffuse>
          <specular>1 1 1 1</specular>
        </material>
      </visual>
      <visual name="rover_amalia_turret_camera_left_visual">
        <pose>0 -0.09 0.0525 0 0 0</pose>
        <geometry>
          <mesh>
            <uri>model://rover_amalia_turret/meshes/camera.dae</uri>
          </mesh>
        </geometry>
        <material>
          <ambient>0.2 0.2 0.2 1</ambient>
          <diffuse>0.1 0.1 0.1 1</diffuse>
          <specular>1 1 1 1</specular>
        </material>
      </visual>
      <visual name="rover_amalia_turret_camera_right_visual">
        <pose>0 0.09 0.0525 0 0 0</pose>
        <geometry>
          <mesh>
            <uri>model://rover_amalia_turret/meshes/camera.dae</uri>
          </mesh>
        </geometry>
        <material>
          <ambient>0.2 0.2 0.2 1</ambient>
          <diffuse>0.1 0.1 0.1 1</diffuse>
          <specular>1 1 1 1</specular>
        </material>
      </visual>
      <visual name="rover_amalia_turret_camera_base">
        <pose>0 0 0.04 0 0 0</pose>
        <geometry>
          <box>
            <size>0.02 0.205 0.001</size>
          </box>
        </geometry>
      </visual>
      <collision name="rover_amalia_turret_payload_collision">
        <pose>0 0 0.08 0 0 0</pose>
        <geometry>
          <box>
            <size>0.07 0.205 0.09</size>
          </box>
        </geometry>
      </collision>
      <sensor name="camera" type="multicamera">
        <always_on>1</always_on>
        <update_rate>60</update_rate>
        <visualize>true</visualize>
        <!--warning: the left and right are inverted, but it is ok -->
        <camera name="left">
          <pose>0 0.09 0.0525 0 0 0</pose>
          <horizontal_fov>1.047</horizontal_fov>
          <image>
            <width>1280</width>
            <height>1024</height>
          </image>
          <clip>
            <near>0.05</near>
            <far>100</far>
          </clip>
        </camera>
        <camera name="right">
          <pose>0 -0.09 0.0525 0 0 0</pose>
          <horizontal_fov>1.047</horizontal_fov>
          <image>
            <width>1280</width>
            <height>1024</height>
          </image>
          <clip>
            <near>0.05</near>
            <far>100</far>
          </clip>
        </camera>
        <plugin filename="libgazebo_ros_multicamera.so" name="stereo_camera_controller">
          <alwaysOn>true</alwaysOn>
          <updateRate>60.0</updateRate>
          <cameraName>stereo</cameraName>
          <imageTopicName>image_raw</imageTopicName>
          <cameraInfoTopicName>camera_info</cameraInfoTopicName>
          <!--TODO: change this, add two frames-->
          <frameName>/rover_amalia_turret_tilt_hinge</frameName>
          <rightFrameName>/rover_amalia_turret_tilt_hinge</rightFrameName>
          <hackBaseline>0.18</hackBaseline>
          <distortionK1>0.0</distortionK1>
          <distortionK2>0.0</distortionK2>
          <distortionK3>0.0</distortionK3>
          <distortionT1>0.0</distortionT1>
          <distortionT2>0.0</distortionT2>
        </plugin>
      </sensor>
      <velocity_decay>
        <linear>0</linear>
        <angular>0</angular>
      </velocity_decay>
      <self_collide>0</self_collide>
      <kinematic>0</kinematic>
      <gravity>0</gravity>
      <inertial>
        <mass>0.000001</mass>
      </inertial>
    </link>
    <link name="rover_amalia_turret_depth_camera_link">
      <pose> 0.2 0 0.824 0 0 0</pose>
      <visual name="rover_amalia_turret_tof_visual">
        <geometry>
          <mesh>
            <uri>model://rover_amalia_turret/meshes/tof.dae</uri>
          </mesh>
        </geometry>
        <material>
          <ambient>0.2 0.2 0.2 1</ambient>
          <diffuse>0.1 0.1 0.1 1</diffuse>
          <specular>1 1 1 1</specular>
        </material>
      </visual>
      <sensor name="depth_camera" type="depth">
        <camera>
          <horizontal_fov>0.767944</horizontal_fov>
          <image>
            <width>176</width>
            <height>144</height>
            <format>R8G8B8</format>
          </image>
          <clip>
            <near>0.05</near>
            <far>5</far>
          </clip>
        </camera>
        <plugin filename="libgazebo_ros_depth_camera.so" name="depth_camera_plugin">
          <alwaysOn>1</alwaysOn>
          <robotNamespace>rover_amalia</robotNamespace>
          <updateRate>25.0</updateRate>
          <imageTopicName>image_raw</imageTopicName>
          <depthImageTopicName>depth_raw</depthImageTopicName>
          <depthImageCameraInfoTopicName>camera_info</depthImageCameraInfoTopicName>
          <pointCloudTopicName>points</pointCloudTopicName>
          <cameraInfoTopicName>camera_info</cameraInfoTopicName>
          <cameraName>depth_cam</cameraName>
          <frameName>/rover_amalia_turret_depth_camera_link</frameName>
          <pointCloudCutoff>0.001</pointCloudCutoff>
          <distortionK1>0.0</distortionK1>
          <distortionK2>0.0</distortionK2>
          <distortionK3>0.0</distortionK3>
          <distortionT1>0.0</distortionT1>
          <distortionT2>0.0</distortionT2>
        </plugin>
        <always_on>true</always_on>
        <update_rate>25.0</update_rate>
      </sensor>
      <self_collide>0</self_collide>
      <kinematic>0</kinematic>
      <gravity>0</gravity>
      <inertial>
        <mass>0.000001</mass>
      </inertial>
    </link>
    <joint name="rover_amalia_hinge_depth_camera_link" type="revolute">
      <child>rover_amalia_turret_depth_camera_link</child>
      <parent>rover_amalia_turret_tilt_hinge</parent>
      <axis>
        <xyz>0 1 0</xyz>
        <limit>
          <lower>-1e-16</lower>
          <upper>1e-16</upper>
          <effort>1000</effort>
          <velocity>1000</velocity>
        </limit>
      </axis>
    </joint>
    <plugin filename="libgazebo_ros_joint_state_publisher.so" name="depth_camera_p">
      <robotNamespace/>
      <jointName>rover_amalia_hinge_depth_camera_link</jointName>
      <updateRate>10</updateRate>
    </plugin>
    <joint name="rover_amalia_turret_pan" type="revolute">
      <child>rover_amalia_turret_tilt_base</child>
      <parent>rover_amalia_turret_bar</parent>
      <axis>
        <xyz>0 0 -1</xyz>
        <limit>
          <lower>-3.1415926</lower>
          <upper>3.1415926</upper>
          <effort>1000</effort>
          <velocity>1000</velocity>
        </limit>
      </axis>
      <physics>
        <ode>
          <cfm>0.0001</cfm>
          <erp>0.2</erp>
        </ode>
      </physics>
    </joint>
    <joint name="rover_amalia_turret_tilt" type="revolute">
      <child>rover_amalia_turret_tilt_hinge</child>
      <parent>rover_amalia_turret_tilt_base</parent>
      <axis>
        <xyz>0 -1 0</xyz>
        <limit>
          <lower>-2.35619445</lower>
          <upper>2.35619445</upper>
          <effort>1000</effort>
          <velocity>1000</velocity>
        </limit>
      </axis>
      <physics>
        <ode>
          <cfm>0.0001</cfm>
          <erp>0.2</erp>
        </ode>
      </physics>
    </joint>
    <plugin filename="libgazebo_ros_joint_commander.so" name="joint_commander">
      <robotNamespace>rover_amalia</robotNamespace>
      <jointSet1>/ptu</jointSet1>
      <jointSet1instantaneous>0</jointSet1instantaneous>
      <jointSet1Joint1>rover_amalia_turret_pan</jointSet1Joint1>
      <jointSet1Joint1speed>1</jointSet1Joint1speed>
      <jointSet1Joint2>rover_amalia_turret_tilt</jointSet1Joint2>
      <jointSet1Joint2speed>1</jointSet1Joint2speed>
    </plugin>
    <plugin filename="libgazebo_ros_joint_state_publisher.so" name="pan">
      <!--keep update rate lower than camera rate-->
      <robotNamespace/>
      <jointName>rover_amalia_turret_pan</jointName>
      <updateRate>20</updateRate>
    </plugin>
    <plugin filename="libgazebo_ros_joint_state_publisher.so" name="tilt">
      <!--keep update rate lower than camera rate-->
      <robotNamespace/>
      <jointName>rover_amalia_turret_tilt</jointName>
      <updateRate>20</updateRate>
    </plugin>
    <pose>0 0 0 0 0 0</pose>
  </model>
</sdf>

