<?xml version="1.0" ?>
<!-- =================================================================================== -->
<!-- |    This document was autogenerated by xacro from /home/clynamen/teamdiana/gazebo-assets/models/definitions/rover_amalia_leg/model.xacro | -->
<!-- |    EDITING THIS FILE BY HAND IS NOT RECOMMENDED                                 | -->
<!-- =================================================================================== -->
<sdf version="1.5">
  <model name="rover_amalia_leg">
    <pose>0 0 0 0 0 0</pose>
    <link name="rover_amalia_leg_bar_f_r">
      <pose>0.0 0.0 0.18 0 0 0</pose>
      <inertial>
        <pose>0 0 0 0 0 0</pose>
        <mass>0.31</mass>
        <inertia>
          <ixx>0.00279048</ixx>
          <ixy>0</ixy>
          <ixz>-0.00003956</ixz>
          <iyy>0.00275062</iyy>
          <iyz>0</iyz>
          <izz>0.00008316</izz>
        </inertia>
      </inertial>
      <collision name="leg_bar_f_r_bar_collision">
        <geometry>
          <cylinder>
            <length>0.2</length>
            <radius>0.008</radius>
          </cylinder>
        </geometry>
        <max_contacts>10</max_contacts>
      </collision>
      <visual name="rover_amalia_leg_bar_f_r_bar_visual">
        <pose>0 -0.018 0 0 0 0.0</pose>
        <geometry>
          <mesh>
            <uri>model://rover_amalia_leg/meshes/leg.dae</uri>
          </mesh>
        </geometry>
      </visual>
    </link>
    <link name="rover_amalia_leg_wheel_f_r">
      <pose>0.0 0.053 0.08 0 0 0</pose>
      <inertial>
        <pose>0 0 0 0 0 0</pose>
        <mass>1.1</mass>
        <inertia>
          <ixx>0.00222713</ixx>
          <iyy>0.00353418</iyy>
          <izz>0.00222499</izz>
          <ixy>0</ixy>
          <ixz>0</ixz>
          <iyz>0</iyz>
        </inertia>
      </inertial>
      <collision name="rover_amalia_leg_wheel_f_r_collision">
        <pose>0 0 0 1.5707963 0 0</pose>
        <geometry>
          <cylinder>
            <length>0.07</length>
            <radius>0.08</radius>
          </cylinder>
        </geometry>
        <max_contacts>10</max_contacts>
      </collision>
      <visual name="rover_amalia_leg_wheel_f_r_motor_visual">
        <pose>0 0 0 0 0 0.0</pose>
        <geometry>
          <mesh>
            <uri>model://rover_amalia_leg/meshes/motor.dae</uri>
          </mesh>
        </geometry>
        <material>
          <ambient>1 0.647 0 1</ambient>
          <diffuse>1 0.647 0 1</diffuse>
          <specular>1 1 1 0.6</specular>
        </material>
      </visual>
      <visual name="rover_amalia_leg_wheel_f_r_tire_visual">
        <pose>0 0 0 0 0 0.0</pose>
        <geometry>
          <mesh>
            <uri>model://rover_amalia_leg/meshes/tire.dae</uri>
          </mesh>
        </geometry>
        <material>
          <ambient>0.1 0.1 0.1 1</ambient>
          <diffuse>0 0 0 1</diffuse>
          <specular>1 1 1 1</specular>
        </material>
      </visual>
      <self_collide>0</self_collide>
      <kinematic>0</kinematic>
      <gravity>1</gravity>
    </link>
    <joint name="rover_amalia_leg_shaft_f_r" type="revolute">
      <child>rover_amalia_leg_wheel_f_r</child>
      <parent>rover_amalia_leg_bar_f_r</parent>
      <axis>
        <xyz>0 1 0</xyz>
        <limit>
          <lower>-1e+16</lower>
          <upper>1e+16</upper>
          <effort>1000</effort>
          <velocity>1000</velocity>
        </limit>
        <use_parent_model_frame>1</use_parent_model_frame>
      </axis>
    </joint>
    <plugin filename="libgazebo_ros_joint_state_publisher.so" name="wheel_f_r">
      <robotNamespace/>
      <jointName>rover_amalia_leg_shaft_f_r</jointName>
      <updateRate>30</updateRate>
    </plugin>
  </model>
</sdf>

