<?xml version="1.0" ?>
<!-- =================================================================================== -->
<!-- |    This document was autogenerated by xacro from /home/clynamen/teamdiana/gazebo/models/definitions/rover_amalia_leg/model.xacro | -->
<!-- |    EDITING THIS FILE BY HAND IS NOT RECOMMENDED                                 | -->
<!-- =================================================================================== -->
<sdf version="1.5">
  <model name="rover_amalia_leg">
    <pose>0 0 0 0 0 0</pose>
    <link name="rover_amalia_leg_bar_f_r">
      <pose>0.0 0.0 0.18 0 0 0</pose>
      <collision name="leg_bar_f_r_bar_collision">
        <geometry>
          <cylinder>
            <length>0.2</length>
            <radius>0.008</radius>
          </cylinder>
        </geometry>
        <max_contacts>10</max_contacts>
        <surface>
          <contact>
            <ode/>
          </contact>
          <bounce/>
          <friction>
            <ode/>
          </friction>
        </surface>
      </collision>
      <visual name="rover_amalia_leg_bar_f_r_bar_visual">
        <pose>0 0 0 0 0 0</pose>
        <geometry>
          <cylinder>
            <length>0.2</length>
            <radius>0.008</radius>
          </cylinder>
        </geometry>
      </visual>
    </link>
    <link name="rover_amalia_leg_wheel_f_r">
      <pose>0.0 0.044 0.08 0 0 0</pose>
      <inertial>
        <pose>0 0 0 0 0 0</pose>
        <mass>5</mass>
        <inertia>
          <ixx>100</ixx>
          <ixy>0</ixy>
          <ixz>0</ixz>
          <iyy>100</iyy>
          <iyz>0</iyz>
          <izz>100</izz>
        </inertia>
      </inertial>
      <collision name="rover_amalia_leg_wheel_f_r_collision">
        <pose>0 0 0 1.5707963 0 0</pose>
        <geometry>
          <cylinder>
            <length>0.07</length>
            <radius>0.08</radius>
          </cylinder>
        </geometry>
        <max_contacts>10</max_contacts>
      </collision>
      <visual name="rover_amalia_leg_wheel_f_r_visual">
        <pose>0 0 0 0 0 0</pose>
        <geometry>
          <mesh>
            <uri>model://rover_amalia_leg/meshes/wheel.dae</uri>
          </mesh>
        </geometry>
      </visual>
      <self_collide>0</self_collide>
      <kinematic>0</kinematic>
      <gravity>1</gravity>
    </link>
    <joint name="rover_amalia_leg_shaft_f_r" type="revolute">
      <child>rover_amalia_leg_wheel_f_r</child>
      <parent>rover_amalia_leg_bar_f_r</parent>
      <axis>
        <xyz>0 1 0</xyz>
        <limit>
          <lower>-1e+16</lower>
          <upper>1e+16</upper>
        </limit>
        <use_parent_model_frame>1</use_parent_model_frame>
      </axis>
    </joint>
  </model>
</sdf>

