<?xml version="1.0" ?>
<sdf version="1.5">
  <model name="rover_amalia">
    <plugin filename="libgazebo_ros_skid_steer_drive.so" name="skid_steer_drive">
      <robotNamespace>rover_amalia</robotNamespace>
      <broadcastTF>1</broadcastTF>
      <leftFrontJoint>shaft_f_l</leftFrontJoint>
      <rightFrontJoint>shaft_f_r</rightFrontJoint>
      <leftRearJoint>shaft_p_l</leftRearJoint>
      <rightRearJoint>shaft_p_r</rightRearJoint>
      <wheelSeparation>0.400</wheelSeparation>
      <wheelDiameter>0.18</wheelDiameter>
      <torque>5.0</torque>
      <commandTopic>cmd_vel</commandTopic>
      <odometryTopic>odom</odometryTopic>
      <odometryFrame>odom</odometryFrame>
      <robotBaseFrame>base_footprint</robotBaseFrame>
      <updateRate>100.0</updateRate>
    </plugin>
    <static>0</static>
    <link name="chassis">
      <pose>0 0 0 0 0 0</pose>
      <inertial>
        <pose>0.0216667 0 -0.0215556 0 -0 0</pose>
        <mass>9</mass>
        <inertia>
          <ixx>900.12</ixx>
          <ixy>-3.46945e-18</ixy>
          <ixz>-0.0139533</ixz>
          <iyy>900.352</iyy>
          <iyz>0</iyz>
          <izz>900.455</izz>
        </inertia>
      </inertial>
      <collision name="chassis_collision">
        <pose>0 0 0 0 -0 0</pose>
        <geometry>
          <box>
            <size>0.492 0.334 0.1</size>
          </box>
        </geometry>
        <max_contacts>10</max_contacts>
        <surface>
          <contact>
            <ode/>
          </contact>
          <bounce/>
          <friction>
            <ode/>
          </friction>
        </surface>
      </collision>
      <collision name="chassis_collision_base">
        <pose>0.195 0 0.073 0 -0 0</pose>
        <geometry>
          <box>
            <size>0.089 0.064 0.046</size>
          </box>
        </geometry>
        <max_contacts>10</max_contacts>
        <surface>
          <contact>
            <ode/>
          </contact>
          <bounce/>
          <friction>
            <ode/>
          </friction>
        </surface>
      </collision>
      <collision name="chassis_collision_leg_f_l">
        <pose>0.177943 0.19 -0.0987583 0 -0.5 0</pose>
        <geometry>
          <cylinder>
            <length>0.2</length>
            <radius>0.008</radius>
          </cylinder>
        </geometry>
        <max_contacts>10</max_contacts>
        <surface>
          <contact>
            <ode/>
          </contact>
          <bounce/>
          <friction>
            <ode/>
          </friction>
        </surface>
      </collision>
      <collision name="chassis_collision_leg_f_r">
        <pose>0.177943 -0.19 -0.0987583 0 -0.5 0</pose>
        <geometry>
          <cylinder>
            <length>0.2</length>
            <radius>0.008</radius>
          </cylinder>
        </geometry>
        <max_contacts>10</max_contacts>
        <surface>
          <contact>
            <ode/>
          </contact>
          <bounce/>
          <friction>
            <ode/>
          </friction>
        </surface>
      </collision>
      <collision name="chassis_collision_leg_p_l">
        <pose>-0.177943 0.19 -0.0987583 0 0.5 0</pose>
        <geometry>
          <cylinder>
            <length>0.2</length>
            <radius>0.008</radius>
          </cylinder>
        </geometry>
        <max_contacts>10</max_contacts>
        <surface>
          <contact>
            <ode/>
          </contact>
          <bounce/>
          <friction>
            <ode/>
          </friction>
        </surface>
      </collision>
      <collision name="chassis_collision_leg_p_r">
        <pose>-0.177943 -0.19 -0.0987583 0 0.5 0</pose>
        <geometry>
          <cylinder>
            <length>0.2</length>
            <radius>0.008</radius>
          </cylinder>
        </geometry>
        <max_contacts>10</max_contacts>
        <surface>
          <contact>
            <ode/>
          </contact>
          <bounce/>
          <friction>
            <ode/>
          </friction>
        </surface>
      </collision>
      <visual name="chassis_visual">
        <pose>0 0 0 0 -0 0</pose>
        <geometry>
          <box>
            <size>0.492 0.334 0.1</size>
          </box>
        </geometry>
      </visual>
      <visual name="chassis_visual_Range_Front">
        <pose>0.246 0 -0.05 0 -0 0</pose>
        <geometry>
          <box>
            <size>0.01 0.03 0.01</size>
          </box>
        </geometry>
      </visual>
      <visual name="chassis_visual_Range_Front_Down">
        <pose>0.246 0 -0.05 0 1.57 0</pose>
        <geometry>
          <box>
            <size>0.01 0.03 0.01</size>
          </box>
        </geometry>
      </visual>
      <visual name="chassis_visual_Range_Post">
        <pose>-0.246 0 -0.05 3.14159 0.00159265 3.14159</pose>
        <geometry>
          <box>
            <size>0.01 0.03 0.01</size>
          </box>
        </geometry>
      </visual>
      <visual name="chassis_visual_Range_Post_Down">
        <pose>-0.246 0 -0.05 0 1.57 0</pose>
        <geometry>
          <box>
            <size>0.01 0.03 0.01</size>
          </box>
        </geometry>
      </visual>
      <visual name="chassis_visual_base">
        <pose>0.195 0 0.073 0 -0 0</pose>
        <geometry>
          <box>
            <size>0.089 0.064 0.046</size>
          </box>
        </geometry>
      </visual>
      <visual name="chassis_visual_leg_f_l">
        <pose>0.177943 0.19 -0.0987583 0 -0.5 0</pose>
        <geometry>
          <cylinder>
            <length>0.2</length>
            <radius>0.008</radius>
          </cylinder>
        </geometry>
      </visual>
      <visual name="chassis_visual_leg_f_r">
        <pose>0.177943 -0.19 -0.0987583 0 -0.5 0</pose>
        <geometry>
          <cylinder>
            <length>0.2</length>
            <radius>0.008</radius>
          </cylinder>
        </geometry>
      </visual>
      <visual name="chassis_visual_leg_p_l">
        <pose>-0.177943 0.19 -0.0987583 0 0.5 0</pose>
        <geometry>
          <cylinder>
            <length>0.2</length>
            <radius>0.008</radius>
          </cylinder>
        </geometry>
      </visual>
      <visual name="chassis_visual_leg_p_r">
        <pose>-0.177943 -0.19 -0.0987583 0 0.5 0</pose>
        <geometry>
          <cylinder>
            <length>0.2</length>
            <radius>0.008</radius>
          </cylinder>
        </geometry>
      </visual>
      <velocity_decay>
        <linear>0</linear>
        <angular>0</angular>
      </velocity_decay>
      <self_collide>0</self_collide>
      <kinematic>0</kinematic>
      <gravity>1</gravity>
    </link>
    <link name="testa">
      <pose>0.2175 -0.012 0.096 0 -0 3.14</pose>
      <inertial>
        <pose>0 0 0 0 -0 0</pose>
        <mass>1</mass>
        <inertia>
          <ixx>100</ixx>
          <ixy>0</ixy>
          <ixz>0</ixz>
          <iyy>100</iyy>
          <iyz>0</iyz>
          <izz>100</izz>
        </inertia>
      </inertial>
      <visual name="testa_visual">
        <pose>0.023 0 0.033 0 -0 0</pose>
        <geometry>
          <box>
            <size>0.09 0.043 0.066</size>
          </box>
        </geometry>
      </visual>
      <velocity_decay>
        <linear>0</linear>
        <angular>0</angular>
      </velocity_decay>
      <self_collide>0</self_collide>
      <kinematic>0</kinematic>
      <gravity>1</gravity>
    </link>
    <joint name="pan" type="revolute">
      <child>testa</child>
      <parent>chassis</parent>
      <axis>
        <xyz>0 0 1</xyz>
        <limit>
          <lower>-1e-16</lower>
          <upper>1e-16</upper>
        </limit>
        <dynamics/>
        <use_parent_model_frame>1</use_parent_model_frame>
      </axis>
    </joint>
    <link name="braccio">
      <pose>0.2175 -0.012 0.14 3.14 -0 3.14</pose>
      <inertial>
        <pose>0 0 -0.02 0 -0 0</pose>
        <mass>2</mass>
        <inertia>
          <ixx>200.001</ixx>
          <ixy>0</ixy>
          <ixz>0</ixz>
          <iyy>200.001</iyy>
          <iyz>0</iyz>
          <izz>200</izz>
        </inertia>
      </inertial>
      <collision name="braccio_collision">
        <pose>0 0 -0.014 0 -0 0</pose>
        <geometry>
          <box>
            <size>0.02 0.061 0.049</size>
          </box>
        </geometry>
        <max_contacts>10</max_contacts>
        <surface>
          <contact>
            <ode/>
          </contact>
          <bounce/>
          <friction>
            <ode/>
          </friction>
        </surface>
      </collision>
      <visual name="braccio_visual">
        <pose>0 0 -0.014 0 -0 0</pose>
        <geometry>
          <box>
            <size>0.02 0.061 0.049</size>
          </box>
        </geometry>
      </visual>
      <visual name="braccio_visual_camera">
        <pose>1.59519e-05 3.18404e-05 -0.06 1.57159 0.00159265 -1.57159</pose>
        <geometry>
          <box>
            <size>0.2 0.04 0.04</size>
          </box>
        </geometry>
      </visual>
      <sensor name="depth_camera" type="depth">
        <pose>0.0 0.0 0.0 0.0 3.14 0.0</pose>
        <camera>
          <horizontal_fov>1.578</horizontal_fov>
          <image>
            <width>640</width>
            <height>480</height>
            <format>R8G8B8</format>
          </image>
          <clip>
            <near>0.4</near>
            <far>100</far>
          </clip>
        </camera>
        <plugin filename="libgazebo_ros_depth_camera.so" name="depth_camera_plugin">
          <alwaysOn>1</alwaysOn>
          <updateRate>10.0</updateRate>
          <imageTopicName>image_raw</imageTopicName>
          <depthImageTopicName>depth_raw</depthImageTopicName>
          <depthImageCameraInfoTopicName>camera_info</depthImageCameraInfoTopicName>
          <pointCloudTopicName>points</pointCloudTopicName>
          <cameraInfoTopicName>camera_info</cameraInfoTopicName>
          <cameraName>depth_cam</cameraName>
          <frameName>/base_link</frameName>
          <pointCloudCutoff>0.001</pointCloudCutoff>
          <distortionK1>0.0</distortionK1>
          <distortionK2>0.0</distortionK2>
          <distortionK3>0.0</distortionK3>
          <distortionT1>0.0</distortionT1>
          <distortionT2>0.0</distortionT2>
        </plugin>
        <always_on>true</always_on>
        <update_rate>10.0</update_rate>
      </sensor>
      <sensor name="camera" type="multicamera">
        <always_on>1</always_on>
        <update_rate>30</update_rate>
        <visualize>true</visualize>
        <camera name="left">
          <pose>0 0 0 0 3.14 0</pose>
          <horizontal_fov>1.047</horizontal_fov>
          <image>
            <width>320</width>
            <height>240</height>
          </image>
          <clip>
            <near>0.4</near>
            <far>100</far>
          </clip>
        </camera>
        <camera name="right">
          <pose>0 -0.2 0 0 3.14 0</pose>
          <horizontal_fov>1.047</horizontal_fov>
          <image>
            <width>320</width>
            <height>240</height>
          </image>
          <clip>
            <near>0.4</near>
            <far>100</far>
          </clip>
        </camera>
        <plugin filename="libgazebo_ros_multicamera.so" name="stereo_camera_controller">
          <alwaysOn>true</alwaysOn>
          <updateRate>0.0</updateRate>
          <cameraName>camera</cameraName>
          <imageTopicName>image_raw</imageTopicName>
          <cameraInfoTopicName>camera_info</cameraInfoTopicName>
          <frameName>left_camera_optical_frame</frameName>
          <!--<rightFrameName>right_camera_optical_frame</rightFrameName>-->
          <hackBaseline>0.07</hackBaseline>
          <distortionK1>0.0</distortionK1>
          <distortionK2>0.0</distortionK2>
          <distortionK3>0.0</distortionK3>
          <distortionT1>0.0</distortionT1>
          <distortionT2>0.0</distortionT2>
        </plugin>
      </sensor>
      <velocity_decay>
        <linear>0</linear>
        <angular>0</angular>
      </velocity_decay>
      <self_collide>0</self_collide>
      <kinematic>0</kinematic>
      <gravity>1</gravity>
    </link>
    <joint name="tilt" type="revolute">
      <child>braccio</child>
      <parent>testa</parent>
      <axis>
        <xyz>-0.001593 -0.999997 -0.001593</xyz>
        <limit>
          <lower>-1e-16</lower>
          <upper>1e-16</upper>
        </limit>
        <dynamics/>
        <use_parent_model_frame>1</use_parent_model_frame>
      </axis>
    </joint>
    <link name="wheel_f_l">
      <pose>0.225885 0.217 -0.186517 0 -0.5 0</pose>
      <inertial>
        <pose>0 0 0 0 -0 0</pose>
        <mass>1</mass>
        <inertia>
          <ixx>100</ixx>
          <ixy>0</ixy>
          <ixz>0</ixz>
          <iyy>100</iyy>
          <iyz>0</iyz>
          <izz>100</izz>
        </inertia>
      </inertial>
      <collision name="wheel_f_l_collision">
        <pose>0 0.035 0 1.57 -0 0</pose>
        <geometry>
          <cylinder>
            <length>0.07</length>
            <radius>0.09</radius>
          </cylinder>
        </geometry>
        <max_contacts>10</max_contacts>
        <surface>
          <contact>
            <ode/>
          </contact>
          <bounce/>
          <friction>
            <ode/>
          </friction>
        </surface>
      </collision>
      <visual name="wheel_f_l_visual">
        <pose>0 0.035 0 1.57 -0 0</pose>
        <geometry>
          <cylinder>
            <length>0.07</length>
            <radius>0.09</radius>
          </cylinder>
        </geometry>
      </visual>
      <velocity_decay>
        <linear>0</linear>
        <angular>0</angular>
      </velocity_decay>
      <self_collide>0</self_collide>
      <kinematic>0</kinematic>
      <gravity>1</gravity>
    </link>
    <joint name="shaft_f_l" type="revolute">
      <child>wheel_f_l</child>
      <parent>chassis</parent>
      <axis>
        <xyz>0 1 0</xyz>
        <limit>
          <lower>-1e+16</lower>
          <upper>1e+16</upper>
        </limit>
        <dynamics/>
        <use_parent_model_frame>1</use_parent_model_frame>
      </axis>
    </joint>
    <link name="wheel_f_r">
      <pose>0.225885 -0.217 -0.186517 0 -0.5 0</pose>
      <inertial>
        <pose>0 0 0 0 -0 0</pose>
        <mass>1</mass>
        <inertia>
          <ixx>100</ixx>
          <ixy>0</ixy>
          <ixz>0</ixz>
          <iyy>100</iyy>
          <iyz>0</iyz>
          <izz>100</izz>
        </inertia>
      </inertial>
      <collision name="wheel_f_r_collision">
        <pose>0 -0.035 0 1.57 -0 0</pose>
        <geometry>
          <cylinder>
            <length>0.07</length>
            <radius>0.09</radius>
          </cylinder>
        </geometry>
        <max_contacts>10</max_contacts>
        <surface>
          <contact>
            <ode/>
          </contact>
          <bounce/>
          <friction>
            <ode/>
          </friction>
        </surface>
      </collision>
      <visual name="wheel_f_r_visual">
        <pose>0 -0.035 0 1.57 -0 0</pose>
        <geometry>
          <cylinder>
            <length>0.07</length>
            <radius>0.09</radius>
          </cylinder>
        </geometry>
      </visual>
      <velocity_decay>
        <linear>0</linear>
        <angular>0</angular>
      </velocity_decay>
      <self_collide>0</self_collide>
      <kinematic>0</kinematic>
      <gravity>1</gravity>
    </link>
    <joint name="shaft_f_r" type="revolute">
      <child>wheel_f_r</child>
      <parent>chassis</parent>
      <axis>
        <xyz>0 1 0</xyz>
        <limit>
          <lower>-1e+16</lower>
          <upper>1e+16</upper>
        </limit>
        <dynamics/>
        <use_parent_model_frame>1</use_parent_model_frame>
      </axis>
    </joint>
    <link name="wheel_p_l">
      <pose>-0.225885 0.217 -0.186517 0 0.5 0</pose>
      <inertial>
        <pose>0 0 0 0 -0 0</pose>
        <mass>1</mass>
        <inertia>
          <ixx>100</ixx>
          <ixy>0</ixy>
          <ixz>0</ixz>
          <iyy>100</iyy>
          <iyz>0</iyz>
          <izz>100</izz>
        </inertia>
      </inertial>
      <collision name="wheel_p_l_collision">
        <pose>0 0.035 0 1.57 -0 0</pose>
        <geometry>
          <cylinder>
            <length>0.07</length>
            <radius>0.09</radius>
          </cylinder>
        </geometry>
        <max_contacts>10</max_contacts>
        <surface>
          <contact>
            <ode/>
          </contact>
          <bounce/>
          <friction>
            <ode/>
          </friction>
        </surface>
      </collision>
      <visual name="wheel_p_l_visual">
        <pose>0 0.035 0 1.57 -0 0</pose>
        <geometry>
          <cylinder>
            <length>0.07</length>
            <radius>0.09</radius>
          </cylinder>
        </geometry>
      </visual>
      <velocity_decay>
        <linear>0</linear>
        <angular>0</angular>
      </velocity_decay>
      <self_collide>0</self_collide>
      <kinematic>0</kinematic>
      <gravity>1</gravity>
    </link>
    <joint name="shaft_p_l" type="revolute">
      <child>wheel_p_l</child>
      <parent>chassis</parent>
      <axis>
        <xyz>0 1 0</xyz>
        <limit>
          <lower>-1e+16</lower>
          <upper>1e+16</upper>
        </limit>
        <dynamics/>
        <use_parent_model_frame>1</use_parent_model_frame>
      </axis>
    </joint>
    <link name="wheel_p_r">
      <pose>-0.225885 -0.217 -0.186517 0 0.5 0</pose>
      <inertial>
        <pose>0 0 0 0 -0 0</pose>
        <mass>1</mass>
        <inertia>
          <ixx>100</ixx>
          <ixy>0</ixy>
          <ixz>0</ixz>
          <iyy>100</iyy>
          <iyz>0</iyz>
          <izz>100</izz>
        </inertia>
      </inertial>
      <collision name="wheel_p_r_collision">
        <pose>0 -0.035 0 1.57 -0 0</pose>
        <geometry>
          <cylinder>
            <length>0.07</length>
            <radius>0.09</radius>
          </cylinder>
        </geometry>
        <max_contacts>10</max_contacts>
        <surface>
          <contact>
            <ode/>
          </contact>
          <bounce/>
          <friction>
            <ode/>
          </friction>
        </surface>
      </collision>
      <visual name="wheel_p_r_visual">
        <pose>0 -0.035 0 1.57 -0 0</pose>
        <geometry>
          <cylinder>
            <length>0.07</length>
            <radius>0.09</radius>
          </cylinder>
        </geometry>
      </visual>
      <velocity_decay>
        <linear>0</linear>
        <angular>0</angular>
      </velocity_decay>
      <self_collide>0</self_collide>
      <kinematic>0</kinematic>
      <gravity>1</gravity>
    </link>
    <joint name="shaft_p_r" type="revolute">
      <child>wheel_p_r</child>
      <parent>chassis</parent>
      <axis>
        <xyz>0 1 0</xyz>
        <limit>
          <lower>-1e+16</lower>
          <upper>1e+16</upper>
        </limit>
        <dynamics/>
        <use_parent_model_frame>1</use_parent_model_frame>
      </axis>
    </joint>
    <pose>0 0 0 0 0 0</pose>
  </model>
</sdf>

